Workbook
Name __123Graph_ACURRENT: [1]FitOutConfCentre!#REF!
Name _SEC15030: #REF!
Name _SEC15030: #REF!
Name _SEC15030: #REF!
Name _SEC15030: #REF!
Name _SEC15060: #REF!
Name _SEC15060: #REF!
Name _SEC15060: #REF!
Name _SEC15060: #REF!
Name _SEC15100: #REF!
Name _SEC15100: #REF!
Name _SEC15100: #REF!
Name _SEC15100: #REF!
Name _SEC15110: #REF!
Name _SEC15110: #REF!
Name _SEC15110: #REF!
Name _SEC15110: #REF!
Name _SEC15125: #REF!
Name _SEC15125: #REF!
Name _SEC15125: #REF!
Name _SEC15125: #REF!
Name _SEC15160: #REF!
Name _SEC15160: #REF!
Name _SEC15160: #REF!
Name _SEC15160: #REF!
Name _SEC15175: #REF!
Name _SEC15175: #REF!
Name _SEC15175: #REF!
Name _SEC15175: #REF!
Name _SEC15290: #REF!
Name _SEC15290: #REF!
Name _SEC15290: #REF!
Name _SEC15290: #REF!
Name _SEC15310: #REF!
Name _SEC15310: #REF!
Name _SEC15310: #REF!
Name _SEC15310: #REF!
Name _SEC15420: #REF!
Name _SEC15420: #REF!
Name _SEC15420: #REF!
Name _SEC15420: #REF!
Name _SEC15440: #REF!
Name _SEC15440: #REF!
Name _SEC15440: #REF!
Name _SEC15440: #REF!
Name _SEC15470: #REF!
Name _SEC15470: #REF!
Name _SEC15470: #REF!
Name _SEC15470: #REF!
Name _SEC15486: #REF!
Name _SEC15486: #REF!
Name _SEC15486: #REF!
Name _SEC15486: #REF!
Name _SEC15540: #REF!
Name _SEC15540: #REF!
Name _SEC15540: #REF!
Name _SEC15540: #REF!
Name _SEC15610: #REF!
Name _SEC15610: #REF!
Name _SEC15610: #REF!

Sheet Couverture
H2: Date: | I2: =TODAY() -> 46098
E22: Sales List
E24: Panneaux Photovoltaïques
E29: Usage interne uniquement
A44: I.ON Energy Services
A45: Route De Gilly 30 1180 Rolle | E45: Infoline 0800 800 840 | I45: www.ion-e.ch

Sheet Financial Data
A1: Section | B1: Référence | C1: Valeur
A2: COEFICIENTS SYSTEME SOLAIRE
A3: Matériel | B3: Accessoires | C3: 0.03
A4: Approvisionnement | B4: Expédition | C4: 0
B5: Douanes | C5: 0
B6: Frais Supplémentaires | C6: 0.02
B7: Transport | C7: 0.05
A8: Construction | B8: Main-d'œuvre Panneaux | C8: 65
B9: Main-d'œuvre Electricité | C9: 90
B10: Project Management | C10: =8*C9+480 -> 1200
B11: Frais Administratifs | C11: =10*C9 -> 900
A12: Sales | B12: Frais Généraux Sales | C12: 0.15
A13: Profit | B13: Profit Approvisionnement | C13: 0.25
B14: Profit Construction | C14: 0.25
A16: COEFICIENTS BATTERIES ET BORNES DE RECHARGE
A17: Matériel | B17: Accessoires | C17: 0
A18: Construction | B18: Project Management | C18: 0.07
B19: Frais Administratifs | C19: 0.06
A20: Profit | B20: Profit Approvisionnement | C20: 0.1925
B21: Profit Construction | C21: 0.1925
A23: Marques | B23: Référence | C23: Coût HT
A24: PANNEAUX
A25: Jinko | B25: JINKO JKM455N-54HL4R-V | C25: 52.4
B26: JINKO JKM465N-48QL6-DB | C26: 62.45
A27: Longi | B27: LONGi Hi-MO X10 Explorer LR7-54HVH-485M | C27: 75.35
B28: LONGi Hi-MO X10 Artist LR7-54HVB-485M | C28: 105.55
A29: Aiko | B29: AIKO Neostar G3 3P54 A480-MCE54Mw | C29: 74.3
B30: AIKO Neostar G3 3S54 A485-MCE54Mb | C30: 102.95
A32: ONDULEURS
A33: Huawei (Hybrid) | B33: SUN2000-6K-MAP0 | C33: 900.85
B34: SUN2000-8K-MAP0 | C34: 1068.05
B35: SUN2000-10K-MAP0 | C35: 1199.9
B36: SUN2000-12K-MAP0 | C36: 1296.35
B37: SUN2000-15K-MB0 | C37: 1731.05
B38: SUN2000-17K-MB0 | C38: 1766.4
B39: SUN2000-20K-MB0 | C39: 1865.8
B40: EMMA-A02 | C40: 251
B41: Optimiseur (/panneau) | C41: 27
A42: Fronius (Hybrid) | B42: Symo GEN24 6.0 SC | C42: 1333.85
B43: Symo GEN24 8.0 SC | C43: 1612.7
...

Sheet Technical Data
A1: PANNEAUX
A2: Marques | B2: Références | C2: Puissance | D2: Garantie Produit | E2: Garantie Production | F2: Solidité | H2: Rendement | I2: Sales List Code (usage interne)
A3: Jinko | B3: ='Financial Data'!B25 -> JINKO JKM455N-54HL4R-V | C3: 455 W | D3: 15 | E3: 30 | G3: X | H3: 0.227 | I3: Jinko 455W Non Full Black
B4: ='Financial Data'!B26 -> JINKO JKM465N-48QL6-DB | C4: 465 W | D4: 15 | E4: 30 | F4: X | H4: 0.2327 | I4: Jinko 465W Full Black
A5: Longi | B5: ='Financial Data'!B27 -> LONGi Hi-MO X10 Explorer LR7-54HVH-485M | C5: 485 W | D5: 30 | E5: 30 | G5: X | H5: 0.238 | I5: Longi 485W Non Full Black
B6: ='Financial Data'!B28 -> LONGi Hi-MO X10 Artist LR7-54HVB-485M | C6: 485 W | D6: 30 | E6: 30 | G6: X | H6: 0.238 | I6: Longi 485W Full Black
A7: Aiko | B7: ='Financial Data'!B29 -> AIKO Neostar G3 3P54 A480-MCE54Mw | C7: 480 W | D7: 25 | E7: 30 | G7: X | H7: 0.24 | I7: Aiko 480W Non Full Black
B8: ='Financial Data'!B30 -> AIKO Neostar G3 3S54 A485-MCE54Mb | C8: 485 W | D8: 25 | E8: 30 | G8: X | H8: 0.243 | I8: Aiko 485W Full Black
A10: ONDULEURS
A11: Marques | B11: Références | C11: Puissance | D11: Garantie Basique | F11: MPPT | G11: Entrée | L11: Parafoudre intégré | N11: Back up
A12: Huawei (Hybrid) | B12: ='Financial Data'!B33 -> SUN2000-6K-MAP0 | C12: 6 KVA | D12: 10 | F12: 2 | G12: 1 | L12: X | N12: non | O12: non
B13: ='Financial Data'!B34 -> SUN2000-8K-MAP0 | C13: 8 KVA | D13: 10 | F13: 2 | G13: 1 | L13: X | N13: non | O13: non
B14: ='Financial Data'!B35 -> SUN2000-10K-MAP0 | C14: 10 KVA | D14: 10 | F14: 2 | G14: 1 | L14: X | N14: non | O14: non
B15: ='Financial Data'!B36 -> SUN2000-12K-MAP0 | C15: 12 KVA | D15: 10 | F15: 2 | G15: 1 | L15: X | N15: non | O15: non
B16: ='Financial Data'!B37 -> SUN2000-15K-MB0 | C16: 15 KVA | D16: 10 | F16: 2 | G16: 2 | L16: X | N16: non | O16: non
B17: ='Financial Data'!B38 -> SUN2000-17K-MB0 | C17: 17 KVA | D17: 10 | F17: 2 | G17: 2 | L17: X | N17: non | O17: non
B18: ='Financial Data'!B39 -> SUN2000-20K-MB0 | C18: 20 KVA | D18: 10 | F18: 2 | G18: 2 | L18: X | N18: non | O18: non
A19: Fronius (Hybrid) | B19: ='Financial Data'!B42 -> Symo GEN24 6.0 SC | C19: 6 KVA | D19: 10 | F19: 2 | G19: 1 | M19: X | N19: oui | O19: non
B20: ='Financial Data'!B43 -> Symo GEN24 8.0 SC | C20: 8 KVA | D20: 10 | F20: 2 | G20: 1 | M20: X | N20: oui | O20: non
B21: ='Financial Data'!B44 -> Symo GEN24 10.0 SC | C21: 10 KVA | D21: 10 | F21: 2 | G21: 1 | M21: X | N21: oui | O21: non
B22: ='Financial Data'!B45 -> Symo GEN24 12.0 SC | C22: 12 KVA | D22: 10 | F22: 2 | G22: 1 | M22: X | N22: oui | O22: non
B23: ='Financial Data'!B46 -> Symo GEN24 6.0 Plus SC | C23: 6 KVA | D23: 10 | F23: 2 | G23: 1 | M23: X | N23: oui | O23: non
B24: ='Financial Data'!B47 -> Symo GEN24 8.0 Plus SC | C24: 8 KVA | D24: 10 | F24: 2 | G24: 1 | M24: X | N24: oui | O24: non
B25: ='Financial Data'!B48 -> Symo GEN24 10.0 Plus SC | C25: 10 KVA | D25: 10 | F25: 2 | G25: 1 | M25: X | N25: oui | O25: non
B26: ='Financial Data'!B49 -> Symo GEN24 12.0 Plus SC | C26: 12 KVA | D26: 10 | F26: 2 | G26: 1 | M26: X | N26: oui | O26: non
B27: ='Financial Data'!B50 -> Verto 15.0 Plus SPD 1+2 | C27: 15 KVA | D27: 5 | F27: 3 | G27: 2 | L27: X | N27: oui | O27: oui
B28: ='Financial Data'!B51 -> Verto 17.5 Plus SPD 1+2 | C28: 17.5 KVA | D28: 5 | F28: 3 | G28: 2 | L28: X | N28: oui | O28: oui
B29: ='Financial Data'!B52 -> Verto 20.0 Plus SPD 1+2 | C29: 20 KVA | D29: 5 | F29: 3 | G29: 2 | L29: X | N29: oui | O29: oui
A30: Fronius (String) | B30: ='Financial Data'!B57 -> Verto 15.0 SPD 1+2 | C30: 15 Kva | D30: 5 | F30: 3 | G30: 2 | L30: X | N30: oui | O30: oui
B31: ='Financial Data'!B58 -> Verto 17.5 SPD 1+2 | C31: 17.5 kva | D31: 5 | F31: 3 | G31: 2 | L31: X | N31: oui | O31: oui
B32: ='Financial Data'!B59 -> Verto 20.0 SPD 1+2 | C32: 20 Kva | D32: 5 | F32: 3 | G32: 2 | L32: X | N32: oui | O32: oui
A34: BATTERIES
A35: Marques | B35: Références | C35: Puissance | D35: Garantie
A36: Huawei | B36: LUNA2000-7-S1 | C36: 7 kWh | D36: 15
B37: LUNA2000-14-S1 | C37: 14 kWh | D37: 15
B38: LUNA2000-21-S1 | C38: 21 kWh | D38: 15
A39: Fronius | B39: ='Financial Data'!B65 -> Reserva 6.3 | C39: 6.3 kWh | D39: 10
B40: ='Financial Data'!B66 -> Reserva 9.5 | C40: 9.5 kWh | D40: 10
B41: ='Financial Data'!B67 -> Reserva 12.6 | C41: 12.6 kWh | D41: 10
B42: ='Financial Data'!B68 -> Reserva 15.8 | C42: 15.8 kWh | D42: 10
...

Sheet Huawei-Hybrid-10 to 50P
A1: N° | B1: DESCRIPTION | C1: QUANTITE | D1: UNITE DE MESURE | E1: PRIX UNITAIRE | F1: PRIX TOTAL | H1: Calcul Matériel | O1: Approvisionnement | U1: Construction | Y1: Sales | Z1: Profit | AB1: P.U. CHF | AC1: TOTAL Approvisionnement | AI1: TOTAL Construction | AM1: Sales | AN1: TOTAL Profit | AP1: TOTAL Frais | AQ1: COUT TOTAL | AR1: PROFIT TOTAL | AS1: PRIX TOTAL | AU1: Appro. Matériel Net | AW1: Main-d'œuvre Construction | AY1: Project Management | BA1: Frais Administratifs et Sales | BC1: Profit | BF1: Cout Total | BH1: Profit | BK1: Prix TTC | BM1: Pronovo | BN1: Prix Pronovo TTC | BO1: Prix TTC/kWc
E2: CHF (HT) | F2: CHF (HT) | H2: Matériel Avant Rabais | L2: Matériel Après Rabais | O2: Matériel Net | P2: Expédition | Q2: Douanes | R2: Frais Supp. | S2: Transport | T2: P.U. Matériel | U2: Main-d'œuvre | V2: Project Management | W2: Frais Administratifs | X2: P.U. Construction | Y2: Frais Généraux Sales | Z2: Profit Appro | AA2: Profit Construction | AC2: TOTAL Matériel Net | AD2: TOTAL Expédition | AE2: TOTAL Douanes | AF2: TOTAL Frais Supp. | AG2: TOTAL Transport | AH2: TOTAL Approvision-nement | AI2: TOTAL Main-d'œuvre | AJ2: TOTAL Project Management | AK2: TOTAL Frais Administratifs | AL2: TOTAL Construction | AM2: TOTAL Frais Généraux Sales | AN2: TOTAL Profit Appro. | AO2: TOTAL Profit Construction | AP2: TOTAL Frais Administratifs et Ingénierie
B3: Choisir le panneau : | H3: MAT (1) | I3: MAT (2) | J3: ACC | K3: Rabais | L3: MAT (1) | M3: MAT (2) | N3: ACC
B4: Jinko 455W Non Full Black | J4: ='Financial Data'!$C$3 -> 0.03 | P4: ='Financial Data'!C4 -> 0 | Q4: ='Financial Data'!C5 -> 0 | R4: ='Financial Data'!C6 -> 0.02 | S4: ='Financial Data'!C7 -> 0.05 | U4: ='Financial Data'!C8 -> 65 | V4: ='Financial Data'!C10 -> 1200 | W4: ='Financial Data'!C11 -> 900 | Y4: ='Financial Data'!C12 -> 0.15 | Z4: ='Financial Data'!C13 -> 0.25 | AA4: ='Financial Data'!C14 -> 0.25
A5: 10 | B5: Panneaux | C5: Puissance: | D5: =ROUNDUP((A5*465)/1000,2) -> 4.65 | F5: =SUM(F6:F15) -> 15043.172 | U5: ='Financial Data'!C9 -> 90 | AC5: =+SUM(AC6:AC15) -> 5381.5955 | AD5: =+SUM(AD6:AD15) -> 0 | AE5: =+SUM(AE6:AE15) -> 0 | AF5: =+SUM(AF6:AF15) -> 107.63191 | AG5: =+SUM(AG6:AG15) -> 192.12977 | AH5: =+SUM(AH6:AH15) -> 5681.3572 | AI5: =+SUM(AI6:AI15) -> 3120 | AJ5: =+SUM(AJ6:AJ15) -> 1200 | ... AS5: =+SUM(AS6:AS15) -> 15043.172 | AT5: =IF(F5=AS5,"Matching","Not Matching") -> Matching | AU5: =SUM(AC5:AG5) -> 5681.3572 | AV5: =AU5/AS5 -> 0.37767015 | AW5: =AI5 -> 3120 | AX5: =AW5/AS5 -> 0.20740306 | AY5: =AJ5 -> 1200 | AZ5: =AY5/AS5 -> 0.079770408 | BA5: =AK5+AM5 -> 2841.4758 | BB5: =BA5/AS5 -> 0.18888807 | BC5: =AN5+AO5 -> 2200.3393 | BD5: =BC5/AS5 -> 0.1462683 | BE5: =IF((AU5+AW5+AY5+BA5+BC5)=AS5,"Matching","Not Matching") -> Matching | BF5: =AQ5 -> 12842.833 | BG5: =BF5/AS5 -> 0.8537317 | BH5: =AR5 -> 2200.3393 | BI5: =BH5/AS5 -> 0.1462683 | BJ5: =IF((BH5+BF5)=AS5,"Matching","Not Matching") -> Matching | BK5: =AS5*1.081 -> 16261.669 | BL5: =ROUND(BK5,-1) -> 16260 | BM5: =D5*380 -> 1767 | BN5: =BK5-BM5 -> 14494.669 | BO5: =BK5/D5 -> 3497.1332
B7: ="Panneau solaire "&G7 -> Panneau solaire JINKO JKM455N-54HL4R-V | C7: =A5 -> 10 | D7: U | E7: =AB7 -> 180.51476 | F7: =C7*E7 -> 1805.1476 | G7: =IF($B4="Jinko 455W Non Full Black",'Technical Data'!B3,IF($B4="Jinko 465W Full Black",'Technical Data'!B4,IF($B4="Longi 485W Non Full Black",'Technical Data'!B5,IF($B4="Longi 485W Full Black",'Technical Data'!B6,IF($B4="Aiko 480W Non Full Black",'Technical Data'!B7,IF($B4="Aiko 485W Full Black",'Technical Data'!B8,IF(ISBLANK($B4)," "))))))) -> JINKO JKM455N-54HL4R-V | H7: =IF($B4="Jinko 455W Non Full Black",'Financial Data'!$C$25,IF($B4="Jinko 465W Full Black",'Financial Data'!$C$26,IF($B4="Longi 485W Non Full Black",'Financial Data'!$C$27,IF($B4="Longi 485W Full Black",'Financial Data'!$C$28,IF($B4="Aiko 480W Non Full Black",'Financial Data'!$C$29,IF($B4="Aiko 485W Full Black",'Financial Data'!$C$30,IF(ISBLANK($B4),'Technical Data'!#REF!))))))) -> 52.4 | I7: 0 | J7: =H7*$J$4 -> 1.572 | K7: 0 | L7: =H7*(1-$K7) -> 52.4 | M7: =I7*(1-$K7) -> 0 | N7: =J7*(1-$K7) -> 1.572 | O7: =(L7+M7+N7) -> 53.972 | P7: =O7*$P$4 -> 0 | Q7: =(O7+P7)*$Q$4 -> 0 | R7: =(O7+P7)*$R$4 -> 1.07944 | S7: =(O7+P7)*$S$4 -> 2.6986 | T7: =SUM(O7:S7) -> 57.75004 | U7: =1*$U$4 -> 65 | V7: 0 | W7: 0 | X7: =SUM(U7:W7) -> 65 | Y7: =$Y$4/(1-$Y$4)*(T7+X7+Z7+AA7) -> 27.077215 | Z7: =T7*$Z$4 -> 14.43751 | AA7: =X7*$AA$4 -> 16.25 | AB7: =T7+X7+Y7+Z7+AA7 -> 180.51476 | AC7: =O7*$C7 -> 539.72 | AD7: =P7*$C7 -> 0 | AE7: =Q7*$C7 -> 0 | AF7: =R7*$C7 -> 10.7944 | AG7: =S7*$C7 -> 26.986 | AH7: =T7*$C7 -> 577.5004 | AI7: =U7*$C7 -> 650 | AJ7: =V7*$C7 -> 0 | ... AO7: =AA7*$C7 -> 162.5 | AP7: =AM7+AK7 -> 270.77215 | AQ7: =AM7+AL7+AH7 -> 1498.2725 | AR7: =AO7+AN7 -> 306.8751 | AS7: =AH7+AL7+AM7+AO7+AN7 -> 1805.1476
B8: ="Onduleur Huawei "&G8 -> Onduleur Huawei SUN2000-6K-MAP0 | C8: 1 | D8: U | E8: =AB8 -> 2119.7012 | F8: =C8*E8 -> 2119.7012 | G8: ='Technical Data'!B12 -> SUN2000-6K-MAP0 | H8: ='Financial Data'!C33 -> 900.85 | I8: ='Financial Data'!$C$40 -> 251 | J8: =H8*$J$4 -> 27.0255 | K8: 0 | L8: =H8*(1-$K8) -> 900.85 | M8: =I8*(1-$K8) -> 251 | N8: =J8*(1-$K8) -> 27.0255 | O8: =(L8+M8+N8) -> 1178.8755 | P8: =O8*$P$4 -> 0 | Q8: =(O8+P8)*$Q$4 -> 0 | R8: =(O8+P8)*$R$4 -> 23.57751 | S8: =(O8+P8)*$S$4 -> 58.943775 | T8: =SUM(O8:S8) -> 1261.3968 | U8: =2*$U$5 -> 180 | V8: 0 | W8: 0 | X8: =SUM(U8:W8) -> 180 | Y8: =$Y$4/(1-$Y$4)*(T8+X8+Z8+AA8) -> 317.95517 | Z8: =T8*$Z$4 -> 315.3492 | AA8: =X8*$AA$4 -> 45 | AB8: =T8+X8+Y8+Z8+AA8 -> 2119.7012 | AC8: =O8*$C8 -> 1178.8755 | AD8: =P8*$C8 -> 0 | AE8: =Q8*$C8 -> 0 | AF8: =R8*$C8 -> 23.57751 | AG8: =S8*$C8 -> 58.943775 | AH8: =T8*$C8 -> 1261.3968 | AI8: =U8*$C8 -> 180 | AJ8: =V8*$C8 -> 0 | ... AO8: =AA8*$C8 -> 45 | AP8: =AM8+AK8 -> 317.95517 | AQ8: =AM8+AL8+AH8 -> 1759.352 | AR8: =AO8+AN8 -> 360.3492 | AS8: =AH8+AL8+AM8+AO8+AN8 -> 2119.7012
B9: Optimiseurs et accessoires | C9: 1 | D9: Forfait | E9: =AB9 -> 1043.4265 | F9: =C9*E9 -> 1043.4265 | H9: 300 | I9: ='Financial Data'!$C$41*C7 -> 270 | J9: =H9*$J$4 -> 9 | K9: 0 | L9: =H9*(1-$K9) -> 300 | M9: =I9*(1-$K9) -> 270 | N9: =J9*(1-$K9) -> 9 | O9: =(L9+M9+N9) -> 579 | P9: =O9*$P$4 -> 0 | Q9: =(O9+P9)*$Q$4 -> 0 | R9: =(O9+P9)*$R$4 -> 11.58 | S9: =(O9+P9)*$S$4 -> 28.95 | T9: =SUM(O9:S9) -> 619.53 | U9: =(C7/10)*$U$5 -> 90 | V9: 0 | W9: 0 | X9: =SUM(U9:W9) -> 90 | Y9: =$Y$4/(1-$Y$4)*(T9+X9+Z9+AA9) -> 156.51397 | Z9: =T9*$Z$4 -> 154.8825 | AA9: =X9*$AA$4 -> 22.5 | AB9: =T9+X9+Y9+Z9+AA9 -> 1043.4265 | AC9: =O9*$C9 -> 579 | AD9: =P9*$C9 -> 0 | AE9: =Q9*$C9 -> 0 | AF9: =R9*$C9 -> 11.58 | AG9: =S9*$C9 -> 28.95 | AH9: =T9*$C9 -> 619.53 | AI9: =U9*$C9 -> 90 | AJ9: =V9*$C9 -> 0 | ... AO9: =AA9*$C9 -> 22.5 | AP9: =AM9+AK9 -> 156.51397 | AQ9: =AM9+AL9+AH9 -> 866.04397 | AR9: =AO9+AN9 -> 177.3825 | AS9: =AH9+AL9+AM9+AO9+AN9 -> 1043.4265
B10: Système de montage sur tuile | C10: =A5 -> 10 | D10: U | E10: =AB10 -> 257.66176 | F10: =C10*E10 -> 2576.6176 | H10: 100 | I10: 0 | J10: =H10*$J$4 -> 3 | K10: 0 | L10: =H10*(1-$K10) -> 100 | M10: =I10*(1-$K10) -> 0 | N10: =J10*(1-$K10) -> 3 | O10: =(L10+M10+N10) -> 103 | P10: =O10*$P$4 -> 0 | Q10: =(O10+P10)*$Q$4 -> 0 | R10: =(O10+P10)*$R$4 -> 2.06 | S10: =(O10+P10)*$S$4 -> 5.15 | T10: =SUM(O10:S10) -> 110.21 | U10: =1*$U$4 -> 65 | V10: 0 | W10: 0 | X10: =SUM(U10:W10) -> 65 | Y10: =$Y$4/(1-$Y$4)*(T10+X10+Z10+AA10) -> 38.649265 | Z10: =T10*$Z$4 -> 27.5525 | AA10: =X10*$AA$4 -> 16.25 | AB10: =T10+X10+Y10+Z10+AA10 -> 257.66176 | AC10: =O10*$C10 -> 1030 | AD10: =P10*$C10 -> 0 | AE10: =Q10*$C10 -> 0 | AF10: =R10*$C10 -> 20.6 | AG10: =S10*$C10 -> 51.5 | AH10: =T10*$C10 -> 1102.1 | AI10: =U10*$C10 -> 650 | AJ10: =V10*$C10 -> 0 | ... AO10: =AA10*$C10 -> 162.5 | AP10: =AM10+AK10 -> 386.49265 | AQ10: =AM10+AL10+AH10 -> 2138.5926 | AR10: =AO10+AN10 -> 438.025 | AS10: =AH10+AL10+AM10+AO10+AN10 -> 2576.6176
B11: Raccordement AC | C11: 1 | D11: Forfait | E11: =AB11 -> 3089.7794 | F11: =C11*E11 -> 3089.7794 | H11: 500 | I11: 0 | J11: =H11*$J$4 -> 15 | K11: 0 | L11: =H11*(1-$K11) -> 500 | M11: =I11*(1-$K11) -> 0 | N11: =J11*(1-$K11) -> 15 | O11: =(L11+M11+N11) -> 515 | P11: =O11*$P$4 -> 0 | Q11: =(O11+P11)*$Q$4 -> 0 | R11: =(O11+P11)*$R$4 -> 10.3 | S11: =(O11+P11)*$S$4 -> 25.75 | T11: =SUM(O11:S11) -> 551.05 | U11: =5*$U$5+600+500 -> 1550 | V11: 0 | W11: 0 | X11: =SUM(U11:W11) -> 1550 | Y11: =$Y$4/(1-$Y$4)*(T11+X11+Z11+AA11) -> 463.46691 | Z11: =T11*$Z$4 -> 137.7625 | AA11: =X11*$AA$4 -> 387.5 | AB11: =T11+X11+Y11+Z11+AA11 -> 3089.7794 | AC11: =O11*$C11 -> 515 | AD11: =P11*$C11 -> 0 | AE11: =Q11*$C11 -> 0 | AF11: =R11*$C11 -> 10.3 | AG11: =S11*$C11 -> 25.75 | AH11: =T11*$C11 -> 551.05 | AI11: =U11*$C11 -> 1550 | AJ11: =V11*$C11 -> 0 | ... AO11: =AA11*$C11 -> 387.5 | AP11: =AM11+AK11 -> 463.46691 | AQ11: =AM11+AL11+AH11 -> 2564.5169 | AR11: =AO11+AN11 -> 525.2625 | AS11: =AH11+AL11+AM11+AO11+AN11 -> 3089.7794
B12: Echafaudage jusqu'à 6m de hauteur | C12: 1 | D12: Forfait | E12: =AB12 -> 2308.5 | F12: =C12*E12 -> 2308.5 | H12: 1300 | I12: 200 | J12: =H12*$J$4 -> 39 | K12: 0 | L12: =H12*(1-$K12) -> 1300 | M12: =I12*(1-$K12) -> 200 | N12: =J12*(1-$K12) -> 39 | O12: =(L12+M12+N12) -> 1539 | P12: =O12*$P$4 -> 0 | Q12: =(O12+P12)*$Q$4 -> 0 | R12: =(O12+P12)*$R$4 -> 30.78 | S12: 0 | T12: =SUM(O12:S12) -> 1569.78 | U12: 0 | V12: 0 | W12: 0 | X12: =SUM(U12:W12) -> 0 | Y12: =$Y$4/(1-$Y$4)*(T12+X12+Z12+AA12) -> 346.275 | Z12: =T12*$Z$4 -> 392.445 | AA12: =X12*$AA$4 -> 0 | AB12: =T12+X12+Y12+Z12+AA12 -> 2308.5 | AC12: =O12*$C12 -> 1539 | AD12: =P12*$C12 -> 0 | AE12: =Q12*$C12 -> 0 | AF12: =R12*$C12 -> 30.78 | AG12: =S12*$C12 -> 0 | AH12: =T12*$C12 -> 1569.78 | AI12: =U12*$C12 -> 0 | AJ12: =V12*$C12 -> 0 | ... AO12: =AA12*$C12 -> 0 | AP12: =AM12+AK12 -> 346.275 | AQ12: =AM12+AL12+AH12 -> 1916.055 | AR12: =AO12+AN12 -> 392.445 | AS12: =AH12+AL12+AM12+AO12+AN12 -> 2308.5
B13: Travaux administratifs | C13: 1 | D13: Forfait | E13: =AB13 -> 900 | F13: =C13*E13 -> 900 | H13: 0 | I13: 0 | J13: =H13*$J$4 -> 0 | K13: 0 | L13: =H13*(1-$K13) -> 0 | M13: =I13*(1-$K13) -> 0 | N13: =J13*(1-$K13) -> 0 | O13: =(L13+M13+N13) -> 0 | P13: =O13*$P$4 -> 0 | Q13: =(O13+P13)*$Q$4 -> 0 | R13: =(O13+P13)*$R$4 -> 0 | S13: 0 | T13: =SUM(O13:S13) -> 0 | U13: 0 | V13: 0 | W13: =$W$4 -> 900 | X13: =SUM(U13:W13) -> 900 | Y13: 0 | Z13: =T13*$Z$4 -> 0 | AA13: 0 | AB13: =T13+X13+Y13+Z13+AA13 -> 900 | AC13: =O13*$C13 -> 0 | AD13: =P13*$C13 -> 0 | AE13: =Q13*$C13 -> 0 | AF13: =R13*$C13 -> 0 | AG13: =S13*$C13 -> 0 | AH13: =T13*$C13 -> 0 | AI13: =U13*$C13 -> 0 | AJ13: =V13*$C13 -> 0 | ... AO13: =AA13*$C13 -> 0 | AP13: =AM13+AK13 -> 900 | AQ13: =AM13+AL13+AH13 -> 900 | AR13: =AO13+AN13 -> 0 | AS13: =AH13+AL13+AM13+AO13+AN13 -> 900
B14: Travaux électriques, contrôle et Pronovo | C14: 1 | D14: Forfait | E14: =AB14 -> 1200 | F14: =C14*E14 -> 1200 | H14: 0 | I14: 0 | J14: =H14*$J$4 -> 0 | K14: 0 | L14: =H14*(1-$K14) -> 0 | M14: =I14*(1-$K14) -> 0 | N14: =J14*(1-$K14) -> 0 | O14: =(L14+M14+N14) -> 0 | P14: =O14*$P$4 -> 0 | Q14: =(O14+P14)*$Q$4 -> 0 | R14: =(O14+P14)*$R$4 -> 0 | S14: 0 | T14: =SUM(O14:S14) -> 0 | U14: 0 | V14: =$V$4 -> 1200 | W14: 0 | X14: =SUM(U14:W14) -> 1200 | Y14: 0 | Z14: =T14*$Z$4 -> 0 | AA14: 0 | AB14: =T14+X14+Y14+Z14+AA14 -> 1200 | AC14: =O14*$C14 -> 0 | AD14: =P14*$C14 -> 0 | AE14: =Q14*$C14 -> 0 | AF14: =R14*$C14 -> 0 | AG14: =S14*$C14 -> 0 | AH14: =T14*$C14 -> 0 | AI14: =U14*$C14 -> 0 | AJ14: =V14*$C14 -> 1200 | ... AO14: =AA14*$C14 -> 0 | AP14: =AM14+AK14 -> 0 | AQ14: =AM14+AL14+AH14 -> 1200 | AR14: =AO14+AN14 -> 0 | AS14: =AH14+AL14+AM14+AO14+AN14 -> 1200
A16: 11 | B16: Panneaux | C16: Puissance: | D16: =ROUNDUP((A16*465)/1000,2) -> 5.12 | F16: =SUM(F17:F26) -> 15537.069 | AC16: =+SUM(AC17:AC26) -> 5565.5675 | AD16: =+SUM(AD17:AD26) -> 0 | AE16: =+SUM(AE17:AE26) -> 0 | AF16: =+SUM(AF17:AF26) -> 111.31135 | AG16: =+SUM(AG17:AG26) -> 201.32837 | AH16: =+SUM(AH17:AH26) -> 5878.2072 | AI16: =+SUM(AI17:AI26) -> 3259 | AJ16: =+SUM(AJ17:AJ26) -> 1200 | ... AS16: =+SUM(AS17:AS26) -> 15537.069 | AT16: =IF(F16=AS16,"Matching","Not Matching") -> Matching | AU16: =SUM(AC16:AG16) -> 5878.2072 | AV16: =AU16/AS16 -> 0.37833436 | AW16: =AI16 -> 3259 | AX16: =AW16/AS16 -> 0.20975642 | AY16: =AJ16 -> 1200 | AZ16: =AY16/AS16 -> 0.077234642 | BA16: =AK16+AM16 -> 2915.5604 | BB16: =BA16/AS16 -> 0.18765189 | BC16: =AN16+AO16 -> 2284.3018 | BD16: =BC16/AS16 -> 0.14702269 | BE16: =IF((AU16+AW16+AY16+BA16+BC16)=AS16,"Matching","Not Matching") -> Matching | BF16: =AQ16 -> 13252.768 | BG16: =BF16/AS16 -> 0.85297731 | BH16: =AR16 -> 2284.3018 | BI16: =BH16/AS16 -> 0.14702269 | BJ16: =IF((BH16+BF16)=AS16,"Matching","Not Matching") -> Matching | BK16: =AS16*1.081 -> 16795.572 | BL16: =ROUND(BK16,-1) -> 16800 | BM16: =D16*380 -> 1945.6 | BN16: =BK16-BM16 -> 14849.972 | BO16: =BK16/D16 -> 3280.3852
B18: ="Panneau solaire "&G18 -> Panneau solaire JINKO JKM455N-54HL4R-V | C18: =A16 -> 11 | D18: U | E18: =AB18 -> 180.51476 | F18: =C18*E18 -> 1985.6624 | G18: =$G$7 -> JINKO JKM455N-54HL4R-V | H18: =H7 -> 52.4 | I18: =I7 -> 0 | J18: =H18*$J$4 -> 1.572 | K18: 0 | L18: =H18*(1-$K18) -> 52.4 | M18: =I18*(1-$K18) -> 0 | N18: =J18*(1-$K18) -> 1.572 | O18: =(L18+M18+N18) -> 53.972 | P18: =O18*$P$4 -> 0 | Q18: =(O18+P18)*$Q$4 -> 0 | R18: =(O18+P18)*$R$4 -> 1.07944 | S18: =(O18+P18)*$S$4 -> 2.6986 | T18: =SUM(O18:S18) -> 57.75004 | U18: =1*$U$4 -> 65 | V18: =V7 -> 0 | W18: =W7 -> 0 | X18: =SUM(U18:W18) -> 65 | Y18: =$Y$4/(1-$Y$4)*(T18+X18+Z18+AA18) -> 27.077215 | Z18: =T18*$Z$4 -> 14.43751 | AA18: =X18*$AA$4 -> 16.25 | AB18: =T18+X18+Y18+Z18+AA18 -> 180.51476 | AC18: =O18*$C18 -> 593.692 | AD18: =P18*$C18 -> 0 | AE18: =Q18*$C18 -> 0 | AF18: =R18*$C18 -> 11.87384 | AG18: =S18*$C18 -> 29.6846 | AH18: =T18*$C18 -> 635.25044 | AI18: =U18*$C18 -> 715 | AJ18: =V18*$C18 -> 0 | ... AO18: =AA18*$C18 -> 178.75 | AP18: =AM18+AK18 -> 297.84936 | AQ18: =AM18+AL18+AH18 -> 1648.0998 | AR18: =AO18+AN18 -> 337.56261 | AS18: =AH18+AL18+AM18+AO18+AN18 -> 1985.6624
B19: ="Onduleur Huawei "&G19 -> Onduleur Huawei SUN2000-6K-MAP0 | C19: 1 | D19: U | E19: =AB19 -> 2119.7012 | F19: =C19*E19 -> 2119.7012 | G19: =$G$8 -> SUN2000-6K-MAP0 | H19: =H8 -> 900.85 | I19: ='Financial Data'!$C$40 -> 251 | J19: =H19*$J$4 -> 27.0255 | K19: 0 | L19: =H19*(1-$K19) -> 900.85 | M19: =I19*(1-$K19) -> 251 | N19: =J19*(1-$K19) -> 27.0255 | O19: =(L19+M19+N19) -> 1178.8755 | P19: =O19*$P$4 -> 0 | Q19: =(O19+P19)*$Q$4 -> 0 | R19: =(O19+P19)*$R$4 -> 23.57751 | S19: =(O19+P19)*$S$4 -> 58.943775 | T19: =SUM(O19:S19) -> 1261.3968 | U19: =2*$U$5 -> 180 | V19: =V8 -> 0 | W19: =W8 -> 0 | X19: =SUM(U19:W19) -> 180 | Y19: =$Y$4/(1-$Y$4)*(T19+X19+Z19+AA19) -> 317.95517 | Z19: =T19*$Z$4 -> 315.3492 | AA19: =X19*$AA$4 -> 45 | AB19: =T19+X19+Y19+Z19+AA19 -> 2119.7012 | AC19: =O19*$C19 -> 1178.8755 | AD19: =P19*$C19 -> 0 | AE19: =Q19*$C19 -> 0 | AF19: =R19*$C19 -> 23.57751 | AG19: =S19*$C19 -> 58.943775 | AH19: =T19*$C19 -> 1261.3968 | AI19: =U19*$C19 -> 180 | AJ19: =V19*$C19 -> 0 | ... AO19: =AA19*$C19 -> 45 | AP19: =AM19+AK19 -> 317.95517 | AQ19: =AM19+AL19+AH19 -> 1759.352 | AR19: =AO19+AN19 -> 360.3492 | AS19: =AH19+AL19+AM19+AO19+AN19 -> 2119.7012
B20: Optimiseurs et accessoires | C20: 1 | D20: Forfait | E20: =AB20 -> 1099.1471 | F20: =C20*E20 -> 1099.1471 | H20: =H9 -> 300 | I20: ='Financial Data'!$C$41*C18 -> 297 | J20: =H20*$J$4 -> 9 | K20: 0 | L20: =H20*(1-$K20) -> 300 | M20: =I20*(1-$K20) -> 297 | N20: =J20*(1-$K20) -> 9 | O20: =(L20+M20+N20) -> 606 | P20: =O20*$P$4 -> 0 | Q20: =(O20+P20)*$Q$4 -> 0 | R20: =(O20+P20)*$R$4 -> 12.12 | S20: =(O20+P20)*$S$4 -> 30.3 | T20: =SUM(O20:S20) -> 648.42 | U20: =(C18/10)*$U$5 -> 99 | V20: =V9 -> 0 | W20: =W9 -> 0 | X20: =SUM(U20:W20) -> 99 | Y20: =$Y$4/(1-$Y$4)*(T20+X20+Z20+AA20) -> 164.87206 | Z20: =T20*$Z$4 -> 162.105 | AA20: =X20*$AA$4 -> 24.75 | AB20: =T20+X20+Y20+Z20+AA20 -> 1099.1471 | AC20: =O20*$C20 -> 606 | AD20: =P20*$C20 -> 0 | AE20: =Q20*$C20 -> 0 | AF20: =R20*$C20 -> 12.12 | AG20: =S20*$C20 -> 30.3 | AH20: =T20*$C20 -> 648.42 | AI20: =U20*$C20 -> 99 | AJ20: =V20*$C20 -> 0 | ... AO20: =AA20*$C20 -> 24.75 | AP20: =AM20+AK20 -> 164.87206 | AQ20: =AM20+AL20+AH20 -> 912.29206 | AR20: =AO20+AN20 -> 186.855 | AS20: =AH20+AL20+AM20+AO20+AN20 -> 1099.1471
B21: Système de montage sur tuile | C21: =A16 -> 11 | D21: U | E21: =AB21 -> 257.66176 | F21: =C21*E21 -> 2834.2794 | H21: =H10 -> 100 | I21: =I10 -> 0 | J21: =H21*$J$4 -> 3 | K21: 0 | L21: =H21*(1-$K21) -> 100 | M21: =I21*(1-$K21) -> 0 | N21: =J21*(1-$K21) -> 3 | O21: =(L21+M21+N21) -> 103 | P21: =O21*$P$4 -> 0 | Q21: =(O21+P21)*$Q$4 -> 0 | R21: =(O21+P21)*$R$4 -> 2.06 | S21: =(O21+P21)*$S$4 -> 5.15 | T21: =SUM(O21:S21) -> 110.21 | U21: =1*$U$4 -> 65 | V21: =V10 -> 0 | W21: =W10 -> 0 | X21: =SUM(U21:W21) -> 65 | Y21: =$Y$4/(1-$Y$4)*(T21+X21+Z21+AA21) -> 38.649265 | Z21: =T21*$Z$4 -> 27.5525 | AA21: =X21*$AA$4 -> 16.25 | AB21: =T21+X21+Y21+Z21+AA21 -> 257.66176 | AC21: =O21*$C21 -> 1133 | AD21: =P21*$C21 -> 0 | AE21: =Q21*$C21 -> 0 | AF21: =R21*$C21 -> 22.66 | AG21: =S21*$C21 -> 56.65 | AH21: =T21*$C21 -> 1212.31 | AI21: =U21*$C21 -> 715 | AJ21: =V21*$C21 -> 0 | ... AO21: =AA21*$C21 -> 178.75 | AP21: =AM21+AK21 -> 425.14191 | AQ21: =AM21+AL21+AH21 -> 2352.4519 | AR21: =AO21+AN21 -> 481.8275 | AS21: =AH21+AL21+AM21+AO21+AN21 -> 2834.2794
B22: Raccordement AC | C22: 1 | D22: Forfait | E22: =AB22 -> 3089.7794 | F22: =C22*E22 -> 3089.7794 | H22: =H11 -> 500 | I22: =I11 -> 0 | J22: =H22*$J$4 -> 15 | K22: 0 | L22: =H22*(1-$K22) -> 500 | M22: =I22*(1-$K22) -> 0 | N22: =J22*(1-$K22) -> 15 | O22: =(L22+M22+N22) -> 515 | P22: =O22*$P$4 -> 0 | Q22: =(O22+P22)*$Q$4 -> 0 | R22: =(O22+P22)*$R$4 -> 10.3 | S22: =(O22+P22)*$S$4 -> 25.75 | T22: =SUM(O22:S22) -> 551.05 | U22: =5*$U$5+600+500 -> 1550 | V22: =V11 -> 0 | W22: =W11 -> 0 | X22: =SUM(U22:W22) -> 1550 | Y22: =$Y$4/(1-$Y$4)*(T22+X22+Z22+AA22) -> 463.46691 | Z22: =T22*$Z$4 -> 137.7625 | AA22: =X22*$AA$4 -> 387.5 | AB22: =T22+X22+Y22+Z22+AA22 -> 3089.7794 | AC22: =O22*$C22 -> 515 | AD22: =P22*$C22 -> 0 | AE22: =Q22*$C22 -> 0 | AF22: =R22*$C22 -> 10.3 | AG22: =S22*$C22 -> 25.75 | AH22: =T22*$C22 -> 551.05 | AI22: =U22*$C22 -> 1550 | AJ22: =V22*$C22 -> 0 | ... AO22: =AA22*$C22 -> 387.5 | AP22: =AM22+AK22 -> 463.46691 | AQ22: =AM22+AL22+AH22 -> 2564.5169 | AR22: =AO22+AN22 -> 525.2625 | AS22: =AH22+AL22+AM22+AO22+AN22 -> 3089.7794
B23: Echafaudage jusqu'à 6m de hauteur | C23: 1 | D23: Forfait | E23: =AB23 -> 2308.5 | F23: =C23*E23 -> 2308.5 | H23: =H12 -> 1300 | I23: =I12 -> 200 | J23: =H23*$J$4 -> 39 | K23: 0 | L23: =H23*(1-$K23) -> 1300 | M23: =I23*(1-$K23) -> 200 | N23: =J23*(1-$K23) -> 39 | O23: =(L23+M23+N23) -> 1539 | P23: =O23*$P$4 -> 0 | Q23: =(O23+P23)*$Q$4 -> 0 | R23: =(O23+P23)*$R$4 -> 30.78 | S23: 0 | T23: =SUM(O23:S23) -> 1569.78 | U23: 0 | V23: =V12 -> 0 | W23: =W12 -> 0 | X23: =SUM(U23:W23) -> 0 | Y23: =$Y$4/(1-$Y$4)*(T23+X23+Z23+AA23) -> 346.275 | Z23: =T23*$Z$4 -> 392.445 | AA23: =X23*$AA$4 -> 0 | AB23: =T23+X23+Y23+Z23+AA23 -> 2308.5 | AC23: =O23*$C23 -> 1539 | AD23: =P23*$C23 -> 0 | AE23: =Q23*$C23 -> 0 | AF23: =R23*$C23 -> 30.78 | AG23: =S23*$C23 -> 0 | AH23: =T23*$C23 -> 1569.78 | AI23: =U23*$C23 -> 0 | AJ23: =V23*$C23 -> 0 | ... AO23: =AA23*$C23 -> 0 | AP23: =AM23+AK23 -> 346.275 | AQ23: =AM23+AL23+AH23 -> 1916.055 | AR23: =AO23+AN23 -> 392.445 | AS23: =AH23+AL23+AM23+AO23+AN23 -> 2308.5
B24: Travaux administratifs | C24: 1 | D24: Forfait | E24: =AB24 -> 900 | F24: =C24*E24 -> 900 | H24: 0 | I24: 0 | J24: =H24*$J$4 -> 0 | K24: 0 | L24: =H24*(1-$K24) -> 0 | M24: =I24*(1-$K24) -> 0 | N24: =J24*(1-$K24) -> 0 | O24: =(L24+M24+N24) -> 0 | P24: =O24*$P$4 -> 0 | Q24: =(O24+P24)*$Q$4 -> 0 | R24: =(O24+P24)*$R$4 -> 0 | S24: 0 | T24: =SUM(O24:S24) -> 0 | U24: 0 | V24: =V13 -> 0 | W24: =W13 -> 900 | X24: =SUM(U24:W24) -> 900 | Y24: 0 | Z24: =T24*$Z$4 -> 0 | AA24: 0 | AB24: =T24+X24+Y24+Z24+AA24 -> 900 | AC24: =O24*$C24 -> 0 | AD24: =P24*$C24 -> 0 | AE24: =Q24*$C24 -> 0 | AF24: =R24*$C24 -> 0 | AG24: =S24*$C24 -> 0 | AH24: =T24*$C24 -> 0 | AI24: =U24*$C24 -> 0 | AJ24: =V24*$C24 -> 0 | ... AO24: =AA24*$C24 -> 0 | AP24: =AM24+AK24 -> 900 | AQ24: =AM24+AL24+AH24 -> 900 | AR24: =AO24+AN24 -> 0 | AS24: =AH24+AL24+AM24+AO24+AN24 -> 900
B25: Travaux électriques, contrôle et Pronovo | C25: 1 | D25: Forfait | E25: =AB25 -> 1200 | F25: =C25*E25 -> 1200 | H25: 0 | I25: 0 | J25: =H25*$J$4 -> 0 | K25: 0 | L25: =H25*(1-$K25) -> 0 | M25: =I25*(1-$K25) -> 0 | N25: =J25*(1-$K25) -> 0 | O25: =(L25+M25+N25) -> 0 | P25: =O25*$P$4 -> 0 | Q25: =(O25+P25)*$Q$4 -> 0 | R25: =(O25+P25)*$R$4 -> 0 | S25: 0 | T25: =SUM(O25:S25) -> 0 | U25: 0 | V25: =V14 -> 1200 | W25: =W14 -> 0 | X25: =SUM(U25:W25) -> 1200 | Y25: 0 | Z25: =T25*$Z$4 -> 0 | AA25: 0 | AB25: =T25+X25+Y25+Z25+AA25 -> 1200 | AC25: =O25*$C25 -> 0 | AD25: =P25*$C25 -> 0 | AE25: =Q25*$C25 -> 0 | AF25: =R25*$C25 -> 0 | AG25: =S25*$C25 -> 0 | AH25: =T25*$C25 -> 0 | AI25: =U25*$C25 -> 0 | AJ25: =V25*$C25 -> 1200 | ... AO25: =AA25*$C25 -> 0 | AP25: =AM25+AK25 -> 0 | AQ25: =AM25+AL25+AH25 -> 1200 | AR25: =AO25+AN25 -> 0 | AS25: =AH25+AL25+AM25+AO25+AN25 -> 1200
A27: 12 | B27: Panneaux | C27: Puissance: | D27: =ROUNDUP((A27*465)/1000,2) -> 5.58 | F27: =SUM(F28:F37) -> 16030.967 | AC27: =+SUM(AC28:AC37) -> 5749.5395 | AD27: =+SUM(AD28:AD37) -> 0 | AE27: =+SUM(AE28:AE37) -> 0 | AF27: =+SUM(AF28:AF37) -> 114.99079 | AG27: =+SUM(AG28:AG37) -> 210.52698 | AH27: =+SUM(AH28:AH37) -> 6075.0573 | AI27: =+SUM(AI28:AI37) -> 3398 | AJ27: =+SUM(AJ28:AJ37) -> 1200 | ... AS27: =+SUM(AS28:AS37) -> 16030.967 | AT27: =IF(F27=AS27,"Matching","Not Matching") -> Matching | AU27: =SUM(AC27:AG27) -> 6075.0573 | AV27: =AU27/AS27 -> 0.37895764 | AW27: =AI27 -> 3398 | AX27: =AW27/AS27 -> 0.21196476 | AY27: =AJ27 -> 1200 | AZ27: =AY27/AS27 -> 0.074855125 | BA27: =AK27+AM27 -> 2989.645 | BB27: =BA27/AS27 -> 0.18649187 | BC27: =AN27+AO27 -> 2368.2643 | BD27: =BC27/AS27 -> 0.1477306 | BE27: =IF((AU27+AW27+AY27+BA27+BC27)=AS27,"Matching","Not Matching") -> Matching | BF27: =AQ27 -> 13662.702 | BG27: =BF27/AS27 -> 0.8522694 | BH27: =AR27 -> 2368.2643 | BI27: =BH27/AS27 -> 0.1477306 | BJ27: =IF((BH27+BF27)=AS27,"Matching","Not Matching") -> Matching | BK27: =AS27*1.081 -> 17329.475 | BL27: =ROUND(BK27,-1) -> 17330 | BM27: =D27*380 -> 2120.4 | BN27: =BK27-BM27 -> 15209.075 | BO27: =BK27/D27 -> 3105.6407
B29: ="Panneau solaire "&G29 -> Panneau solaire JINKO JKM455N-54HL4R-V | C29: =A27 -> 12 | D29: U | E29: =AB29 -> 180.51476 | F29: =C29*E29 -> 2166.1772 | G29: =$G$7 -> JINKO JKM455N-54HL4R-V | H29: =H7 -> 52.4 | I29: =I7 -> 0 | J29: =H29*$J$4 -> 1.572 | K29: 0 | L29: =H29*(1-$K29) -> 52.4 | M29: =I29*(1-$K29) -> 0 | N29: =J29*(1-$K29) -> 1.572 | O29: =(L29+M29+N29) -> 53.972 | P29: =O29*$P$4 -> 0 | Q29: =(O29+P29)*$Q$4 -> 0 | R29: =(O29+P29)*$R$4 -> 1.07944 | S29: =(O29+P29)*$S$4 -> 2.6986 | T29: =SUM(O29:S29) -> 57.75004 | U29: =1*$U$4 -> 65 | V29: =V18 -> 0 | W29: =W18 -> 0 | X29: =SUM(U29:W29) -> 65 | Y29: =$Y$4/(1-$Y$4)*(T29+X29+Z29+AA29) -> 27.077215 | Z29: =T29*$Z$4 -> 14.43751 | AA29: =X29*$AA$4 -> 16.25 | AB29: =T29+X29+Y29+Z29+AA29 -> 180.51476 | AC29: =O29*$C29 -> 647.664 | AD29: =P29*$C29 -> 0 | AE29: =Q29*$C29 -> 0 | AF29: =R29*$C29 -> 12.95328 | AG29: =S29*$C29 -> 32.3832 | AH29: =T29*$C29 -> 693.00048 | AI29: =U29*$C29 -> 780 | AJ29: =V29*$C29 -> 0 | ... AO29: =AA29*$C29 -> 195 | AP29: =AM29+AK29 -> 324.92658 | AQ29: =AM29+AL29+AH29 -> 1797.9271 | AR29: =AO29+AN29 -> 368.25012 | AS29: =AH29+AL29+AM29+AO29+AN29 -> 2166.1772
B30: ="Onduleur Huawei "&G30 -> Onduleur Huawei SUN2000-6K-MAP0 | C30: 1 | D30: U | E30: =AB30 -> 2119.7012 | F30: =C30*E30 -> 2119.7012 | G30: =$G$8 -> SUN2000-6K-MAP0 | H30: =H8 -> 900.85 | I30: ='Financial Data'!$C$40 -> 251 | J30: =H30*$J$4 -> 27.0255 | K30: 0 | L30: =H30*(1-$K30) -> 900.85 | M30: =I30*(1-$K30) -> 251 | N30: =J30*(1-$K30) -> 27.0255 | O30: =(L30+M30+N30) -> 1178.8755 | P30: =O30*$P$4 -> 0 | Q30: =(O30+P30)*$Q$4 -> 0 | R30: =(O30+P30)*$R$4 -> 23.57751 | S30: =(O30+P30)*$S$4 -> 58.943775 | T30: =SUM(O30:S30) -> 1261.3968 | U30: =2*$U$5 -> 180 | V30: =V19 -> 0 | W30: =W19 -> 0 | X30: =SUM(U30:W30) -> 180 | Y30: =$Y$4/(1-$Y$4)*(T30+X30+Z30+AA30) -> 317.95517 | Z30: =T30*$Z$4 -> 315.3492 | AA30: =X30*$AA$4 -> 45 | AB30: =T30+X30+Y30+Z30+AA30 -> 2119.7012 | AC30: =O30*$C30 -> 1178.8755 | AD30: =P30*$C30 -> 0 | AE30: =Q30*$C30 -> 0 | AF30: =R30*$C30 -> 23.57751 | AG30: =S30*$C30 -> 58.943775 | AH30: =T30*$C30 -> 1261.3968 | AI30: =U30*$C30 -> 180 | AJ30: =V30*$C30 -> 0 | ... AO30: =AA30*$C30 -> 45 | AP30: =AM30+AK30 -> 317.95517 | AQ30: =AM30+AL30+AH30 -> 1759.352 | AR30: =AO30+AN30 -> 360.3492 | AS30: =AH30+AL30+AM30+AO30+AN30 -> 2119.7012
B31: Optimiseurs et accessoires | C31: 1 | D31: Forfait | E31: =AB31 -> 1154.8676 | F31: =C31*E31 -> 1154.8676 | H31: =H9 -> 300 | I31: ='Financial Data'!$C$41*C29 -> 324 | J31: =H31*$J$4 -> 9 | K31: 0 | L31: =H31*(1-$K31) -> 300 | M31: =I31*(1-$K31) -> 324 | N31: =J31*(1-$K31) -> 9 | O31: =(L31+M31+N31) -> 633 | P31: =O31*$P$4 -> 0 | Q31: =(O31+P31)*$Q$4 -> 0 | R31: =(O31+P31)*$R$4 -> 12.66 | S31: =(O31+P31)*$S$4 -> 31.65 | T31: =SUM(O31:S31) -> 677.31 | U31: =(C29/10)*$U$5 -> 108 | V31: =V20 -> 0 | W31: =W20 -> 0 | X31: =SUM(U31:W31) -> 108 | Y31: =$Y$4/(1-$Y$4)*(T31+X31+Z31+AA31) -> 173.23015 | Z31: =T31*$Z$4 -> 169.3275 | AA31: =X31*$AA$4 -> 27 | AB31: =T31+X31+Y31+Z31+AA31 -> 1154.8676 | AC31: =O31*$C31 -> 633 | AD31: =P31*$C31 -> 0 | AE31: =Q31*$C31 -> 0 | AF31: =R31*$C31 -> 12.66 | AG31: =S31*$C31 -> 31.65 | AH31: =T31*$C31 -> 677.31 | AI31: =U31*$C31 -> 108 | AJ31: =V31*$C31 -> 0 | ... AO31: =AA31*$C31 -> 27 | AP31: =AM31+AK31 -> 173.23015 | AQ31: =AM31+AL31+AH31 -> 958.54015 | AR31: =AO31+AN31 -> 196.3275 | AS31: =AH31+AL31+AM31+AO31+AN31 -> 1154.8676
B32: Système de montage sur tuile | C32: =A27 -> 12 | D32: U | E32: =AB32 -> 257.66176 | F32: =C32*E32 -> 3091.9412 | H32: =H10 -> 100 | I32: =I10 -> 0 | J32: =H32*$J$4 -> 3 | K32: 0 | L32: =H32*(1-$K32) -> 100 | M32: =I32*(1-$K32) -> 0 | N32: =J32*(1-$K32) -> 3 | O32: =(L32+M32+N32) -> 103 | P32: =O32*$P$4 -> 0 | Q32: =(O32+P32)*$Q$4 -> 0 | R32: =(O32+P32)*$R$4 -> 2.06 | S32: =(O32+P32)*$S$4 -> 5.15 | T32: =SUM(O32:S32) -> 110.21 | U32: =1*$U$4 -> 65 | V32: =V21 -> 0 | W32: =W21 -> 0 | X32: =SUM(U32:W32) -> 65 | Y32: =$Y$4/(1-$Y$4)*(T32+X32+Z32+AA32) -> 38.649265 | Z32: =T32*$Z$4 -> 27.5525 | AA32: =X32*$AA$4 -> 16.25 | AB32: =T32+X32+Y32+Z32+AA32 -> 257.66176 | AC32: =O32*$C32 -> 1236 | AD32: =P32*$C32 -> 0 | AE32: =Q32*$C32 -> 0 | AF32: =R32*$C32 -> 24.72 | AG32: =S32*$C32 -> 61.8 | AH32: =T32*$C32 -> 1322.52 | AI32: =U32*$C32 -> 780 | AJ32: =V32*$C32 -> 0 | ... AO32: =AA32*$C32 -> 195 | AP32: =AM32+AK32 -> 463.79118 | AQ32: =AM32+AL32+AH32 -> 2566.3112 | AR32: =AO32+AN32 -> 525.63 | AS32: =AH32+AL32+AM32+AO32+AN32 -> 3091.9412
B33: Raccordement AC | C33: 1 | D33: Forfait | E33: =AB33 -> 3089.7794 | F33: =C33*E33 -> 3089.7794 | H33: =H11 -> 500 | I33: =I11 -> 0 | J33: =H33*$J$4 -> 15 | K33: 0 | L33: =H33*(1-$K33) -> 500 | M33: =I33*(1-$K33) -> 0 | N33: =J33*(1-$K33) -> 15 | O33: =(L33+M33+N33) -> 515 | P33: =O33*$P$4 -> 0 | Q33: =(O33+P33)*$Q$4 -> 0 | R33: =(O33+P33)*$R$4 -> 10.3 | S33: =(O33+P33)*$S$4 -> 25.75 | T33: =SUM(O33:S33) -> 551.05 | U33: =5*$U$5+600+500 -> 1550 | V33: =V22 -> 0 | W33: =W22 -> 0 | X33: =SUM(U33:W33) -> 1550 | Y33: =$Y$4/(1-$Y$4)*(T33+X33+Z33+AA33) -> 463.46691 | Z33: =T33*$Z$4 -> 137.7625 | AA33: =X33*$AA$4 -> 387.5 | AB33: =T33+X33+Y33+Z33+AA33 -> 3089.7794 | AC33: =O33*$C33 -> 515 | AD33: =P33*$C33 -> 0 | AE33: =Q33*$C33 -> 0 | AF33: =R33*$C33 -> 10.3 | AG33: =S33*$C33 -> 25.75 | AH33: =T33*$C33 -> 551.05 | AI33: =U33*$C33 -> 1550 | AJ33: =V33*$C33 -> 0 | ... AO33: =AA33*$C33 -> 387.5 | AP33: =AM33+AK33 -> 463.46691 | AQ33: =AM33+AL33+AH33 -> 2564.5169 | AR33: =AO33+AN33 -> 525.2625 | AS33: =AH33+AL33+AM33+AO33+AN33 -> 3089.7794
B34: Echafaudage jusqu'à 6m de hauteur | C34: 1 | D34: Forfait | E34: =AB34 -> 2308.5 | F34: =C34*E34 -> 2308.5 | H34: =H12 -> 1300 | I34: =I12 -> 200 | J34: =H34*$J$4 -> 39 | K34: 0 | L34: =H34*(1-$K34) -> 1300 | M34: =I34*(1-$K34) -> 200 | N34: =J34*(1-$K34) -> 39 | O34: =(L34+M34+N34) -> 1539 | P34: =O34*$P$4 -> 0 | Q34: =(O34+P34)*$Q$4 -> 0 | R34: =(O34+P34)*$R$4 -> 30.78 | S34: 0 | T34: =SUM(O34:S34) -> 1569.78 | U34: 0 | V34: =V23 -> 0 | W34: =W23 -> 0 | X34: =SUM(U34:W34) -> 0 | Y34: =$Y$4/(1-$Y$4)*(T34+X34+Z34+AA34) -> 346.275 | Z34: =T34*$Z$4 -> 392.445 | AA34: =X34*$AA$4 -> 0 | AB34: =T34+X34+Y34+Z34+AA34 -> 2308.5 | AC34: =O34*$C34 -> 1539 | AD34: =P34*$C34 -> 0 | AE34: =Q34*$C34 -> 0 | AF34: =R34*$C34 -> 30.78 | AG34: =S34*$C34 -> 0 | AH34: =T34*$C34 -> 1569.78 | AI34: =U34*$C34 -> 0 | AJ34: =V34*$C34 -> 0 | ... AO34: =AA34*$C34 -> 0 | AP34: =AM34+AK34 -> 346.275 | AQ34: =AM34+AL34+AH34 -> 1916.055 | AR34: =AO34+AN34 -> 392.445 | AS34: =AH34+AL34+AM34+AO34+AN34 -> 2308.5
B35: Travaux administratifs | C35: 1 | D35: Forfait | E35: =AB35 -> 900 | F35: =C35*E35 -> 900 | H35: 0 | I35: 0 | J35: =H35*$J$4 -> 0 | K35: 0 | L35: =H35*(1-$K35) -> 0 | M35: =I35*(1-$K35) -> 0 | N35: =J35*(1-$K35) -> 0 | O35: =(L35+M35+N35) -> 0 | P35: =O35*$P$4 -> 0 | Q35: =(O35+P35)*$Q$4 -> 0 | R35: =(O35+P35)*$R$4 -> 0 | S35: 0 | T35: =SUM(O35:S35) -> 0 | U35: 0 | V35: =V24 -> 0 | W35: =W24 -> 900 | X35: =SUM(U35:W35) -> 900 | Y35: 0 | Z35: =T35*$Z$4 -> 0 | AA35: 0 | AB35: =T35+X35+Y35+Z35+AA35 -> 900 | AC35: =O35*$C35 -> 0 | AD35: =P35*$C35 -> 0 | AE35: =Q35*$C35 -> 0 | AF35: =R35*$C35 -> 0 | AG35: =S35*$C35 -> 0 | AH35: =T35*$C35 -> 0 | AI35: =U35*$C35 -> 0 | AJ35: =V35*$C35 -> 0 | ... AO35: =AA35*$C35 -> 0 | AP35: =AM35+AK35 -> 900 | AQ35: =AM35+AL35+AH35 -> 900 | AR35: =AO35+AN35 -> 0 | AS35: =AH35+AL35+AM35+AO35+AN35 -> 900
B36: Travaux électriques, contrôle et Pronovo | C36: 1 | D36: Forfait | E36: =AB36 -> 1200 | F36: =C36*E36 -> 1200 | H36: 0 | I36: 0 | J36: =H36*$J$4 -> 0 | K36: 0 | L36: =H36*(1-$K36) -> 0 | M36: =I36*(1-$K36) -> 0 | N36: =J36*(1-$K36) -> 0 | O36: =(L36+M36+N36) -> 0 | P36: =O36*$P$4 -> 0 | Q36: =(O36+P36)*$Q$4 -> 0 | R36: =(O36+P36)*$R$4 -> 0 | S36: 0 | T36: =SUM(O36:S36) -> 0 | U36: 0 | V36: =V25 -> 1200 | W36: =W25 -> 0 | X36: =SUM(U36:W36) -> 1200 | Y36: 0 | Z36: =T36*$Z$4 -> 0 | AA36: 0 | AB36: =T36+X36+Y36+Z36+AA36 -> 1200 | AC36: =O36*$C36 -> 0 | AD36: =P36*$C36 -> 0 | AE36: =Q36*$C36 -> 0 | AF36: =R36*$C36 -> 0 | AG36: =S36*$C36 -> 0 | AH36: =T36*$C36 -> 0 | AI36: =U36*$C36 -> 0 | AJ36: =V36*$C36 -> 1200 | ... AO36: =AA36*$C36 -> 0 | AP36: =AM36+AK36 -> 0 | AQ36: =AM36+AL36+AH36 -> 1200 | AR36: =AO36+AN36 -> 0 | AS36: =AH36+AL36+AM36+AO36+AN36 -> 1200
A38: 13 | B38: Panneaux | C38: Puissance: | D38: =ROUNDUP((A38*465)/1000,2) -> 6.05 | F38: =SUM(F39:F48) -> 16524.864 | AC38: =+SUM(AC39:AC48) -> 5933.5115 | AD38: =+SUM(AD39:AD48) -> 0 | AE38: =+SUM(AE39:AE48) -> 0 | AF38: =+SUM(AF39:AF48) -> 118.67023 | AG38: =+SUM(AG39:AG48) -> 219.72557 | AH38: =+SUM(AH39:AH48) -> 6271.9073 | AI38: =+SUM(AI39:AI48) -> 3537 | AJ38: =+SUM(AJ39:AJ48) -> 1200 | ... AS38: =+SUM(AS39:AS48) -> 16524.864 | AT38: =IF(F38=AS38,"Matching","Not Matching") -> Matching | AU38: =SUM(AC38:AG38) -> 6271.9073 | AV38: =AU38/AS38 -> 0.37954366 | AW38: =AI38 -> 3537 | AX38: =AW38/AS38 -> 0.2140411 | AY38: =AJ38 -> 1200 | AZ38: =AY38/AS38 -> 0.072617846 | BA38: =AK38+AM38 -> 3063.7296 | BB38: =BA38/AS38 -> 0.1854012 | BC38: =AN38+AO38 -> 2452.2268 | BD38: =BC38/AS38 -> 0.14839619 | BE38: =IF((AU38+AW38+AY38+BA38+BC38)=AS38,"Matching","Not Matching") -> Matching | BF38: =AQ38 -> 14072.637 | BG38: =BF38/AS38 -> 0.85160381 | BH38: =AR38 -> 2452.2268 | BI38: =BH38/AS38 -> 0.14839619 | BJ38: =IF((BH38+BF38)=AS38,"Matching","Not Matching") -> Matching | BK38: =AS38*1.081 -> 17863.378 | BL38: =ROUND(BK38,-1) -> 17860 | BM38: =D38*380 -> 2299 | BN38: =BK38-BM38 -> 15564.378 | BO38: =BK38/D38 -> 2952.6244
B40: ="Panneau solaire "&G40 -> Panneau solaire JINKO JKM455N-54HL4R-V | C40: =A38 -> 13 | D40: U | E40: =AB40 -> 180.51476 | F40: =C40*E40 -> 2346.6919 | G40: =$G$7 -> JINKO JKM455N-54HL4R-V | H40: =H7 -> 52.4 | I40: =I7 -> 0 | J40: =H40*$J$4 -> 1.572 | K40: 0 | L40: =H40*(1-$K40) -> 52.4 | M40: =I40*(1-$K40) -> 0 | N40: =J40*(1-$K40) -> 1.572 | O40: =(L40+M40+N40) -> 53.972 | P40: =O40*$P$4 -> 0 | Q40: =(O40+P40)*$Q$4 -> 0 | R40: =(O40+P40)*$R$4 -> 1.07944 | S40: =(O40+P40)*$S$4 -> 2.6986 | T40: =SUM(O40:S40) -> 57.75004 | U40: =1*$U$4 -> 65 | V40: =V29 -> 0 | W40: =W29 -> 0 | X40: =SUM(U40:W40) -> 65 | Y40: =$Y$4/(1-$Y$4)*(T40+X40+Z40+AA40) -> 27.077215 | Z40: =T40*$Z$4 -> 14.43751 | AA40: =X40*$AA$4 -> 16.25 | AB40: =T40+X40+Y40+Z40+AA40 -> 180.51476 | AC40: =O40*$C40 -> 701.636 | AD40: =P40*$C40 -> 0 | AE40: =Q40*$C40 -> 0 | AF40: =R40*$C40 -> 14.03272 | AG40: =S40*$C40 -> 35.0818 | AH40: =T40*$C40 -> 750.75052 | AI40: =U40*$C40 -> 845 | AJ40: =V40*$C40 -> 0 | ... AO40: =AA40*$C40 -> 211.25 | AP40: =AM40+AK40 -> 352.00379 | AQ40: =AM40+AL40+AH40 -> 1947.7543 | AR40: =AO40+AN40 -> 398.93763 | AS40: =AH40+AL40+AM40+AO40+AN40 -> 2346.6919
B41: ="Onduleur Huawei "&G41 -> Onduleur Huawei SUN2000-6K-MAP0 | C41: 1 | D41: U | E41: =AB41 -> 2119.7012 | F41: =C41*E41 -> 2119.7012 | G41: =$G$8 -> SUN2000-6K-MAP0 | H41: =H8 -> 900.85 | I41: ='Financial Data'!$C$40 -> 251 | J41: =H41*$J$4 -> 27.0255 | K41: 0 | L41: =H41*(1-$K41) -> 900.85 | M41: =I41*(1-$K41) -> 251 | N41: =J41*(1-$K41) -> 27.0255 | O41: =(L41+M41+N41) -> 1178.8755 | P41: =O41*$P$4 -> 0 | Q41: =(O41+P41)*$Q$4 -> 0 | R41: =(O41+P41)*$R$4 -> 23.57751 | S41: =(O41+P41)*$S$4 -> 58.943775 | T41: =SUM(O41:S41) -> 1261.3968 | U41: =2*$U$5 -> 180 | V41: =V30 -> 0 | W41: =W30 -> 0 | X41: =SUM(U41:W41) -> 180 | Y41: =$Y$4/(1-$Y$4)*(T41+X41+Z41+AA41) -> 317.95517 | Z41: =T41*$Z$4 -> 315.3492 | AA41: =X41*$AA$4 -> 45 | AB41: =T41+X41+Y41+Z41+AA41 -> 2119.7012 | AC41: =O41*$C41 -> 1178.8755 | AD41: =P41*$C41 -> 0 | AE41: =Q41*$C41 -> 0 | AF41: =R41*$C41 -> 23.57751 | AG41: =S41*$C41 -> 58.943775 | AH41: =T41*$C41 -> 1261.3968 | AI41: =U41*$C41 -> 180 | AJ41: =V41*$C41 -> 0 | ... AO41: =AA41*$C41 -> 45 | AP41: =AM41+AK41 -> 317.95517 | AQ41: =AM41+AL41+AH41 -> 1759.352 | AR41: =AO41+AN41 -> 360.3492 | AS41: =AH41+AL41+AM41+AO41+AN41 -> 2119.7012
B42: Optimiseurs et accessoires | C42: 1 | D42: Forfait | E42: =AB42 -> 1210.5882 | F42: =C42*E42 -> 1210.5882 | H42: =H9 -> 300 | I42: ='Financial Data'!$C$41*C40 -> 351 | J42: =H42*$J$4 -> 9 | K42: 0 | L42: =H42*(1-$K42) -> 300 | M42: =I42*(1-$K42) -> 351 | N42: =J42*(1-$K42) -> 9 | O42: =(L42+M42+N42) -> 660 | P42: =O42*$P$4 -> 0 | Q42: =(O42+P42)*$Q$4 -> 0 | R42: =(O42+P42)*$R$4 -> 13.2 | S42: =(O42+P42)*$S$4 -> 33 | T42: =SUM(O42:S42) -> 706.2 | U42: =(C40/10)*$U$5 -> 117 | V42: =V31 -> 0 | W42: =W31 -> 0 | X42: =SUM(U42:W42) -> 117 | Y42: =$Y$4/(1-$Y$4)*(T42+X42+Z42+AA42) -> 181.58824 | Z42: =T42*$Z$4 -> 176.55 | AA42: =X42*$AA$4 -> 29.25 | AB42: =T42+X42+Y42+Z42+AA42 -> 1210.5882 | AC42: =O42*$C42 -> 660 | AD42: =P42*$C42 -> 0 | AE42: =Q42*$C42 -> 0 | AF42: =R42*$C42 -> 13.2 | AG42: =S42*$C42 -> 33 | AH42: =T42*$C42 -> 706.2 | AI42: =U42*$C42 -> 117 | AJ42: =V42*$C42 -> 0 | ... AO42: =AA42*$C42 -> 29.25 | AP42: =AM42+AK42 -> 181.58824 | AQ42: =AM42+AL42+AH42 -> 1004.7882 | AR42: =AO42+AN42 -> 205.8 | AS42: =AH42+AL42+AM42+AO42+AN42 -> 1210.5882
B43: Système de montage sur tuile | C43: =A38 -> 13 | D43: U | E43: =AB43 -> 257.66176 | F43: =C43*E43 -> 3349.6029 | H43: =H10 -> 100 | I43: =I10 -> 0 | J43: =H43*$J$4 -> 3 | K43: 0 | L43: =H43*(1-$K43) -> 100 | M43: =I43*(1-$K43) -> 0 | N43: =J43*(1-$K43) -> 3 | O43: =(L43+M43+N43) -> 103 | P43: =O43*$P$4 -> 0 | Q43: =(O43+P43)*$Q$4 -> 0 | R43: =(O43+P43)*$R$4 -> 2.06 | S43: =(O43+P43)*$S$4 -> 5.15 | T43: =SUM(O43:S43) -> 110.21 | U43: =1*$U$4 -> 65 | V43: =V32 -> 0 | W43: =W32 -> 0 | X43: =SUM(U43:W43) -> 65 | Y43: =$Y$4/(1-$Y$4)*(T43+X43+Z43+AA43) -> 38.649265 | Z43: =T43*$Z$4 -> 27.5525 | AA43: =X43*$AA$4 -> 16.25 | AB43: =T43+X43+Y43+Z43+AA43 -> 257.66176 | AC43: =O43*$C43 -> 1339 | AD43: =P43*$C43 -> 0 | AE43: =Q43*$C43 -> 0 | AF43: =R43*$C43 -> 26.78 | AG43: =S43*$C43 -> 66.95 | AH43: =T43*$C43 -> 1432.73 | AI43: =U43*$C43 -> 845 | AJ43: =V43*$C43 -> 0 | ... AO43: =AA43*$C43 -> 211.25 | AP43: =AM43+AK43 -> 502.44044 | AQ43: =AM43+AL43+AH43 -> 2780.1704 | AR43: =AO43+AN43 -> 569.4325 | AS43: =AH43+AL43+AM43+AO43+AN43 -> 3349.6029
B44: Raccordement AC | C44: 1 | D44: Forfait | E44: =AB44 -> 3089.7794 | F44: =C44*E44 -> 3089.7794 | H44: =H11 -> 500 | I44: =I11 -> 0 | J44: =H44*$J$4 -> 15 | K44: 0 | L44: =H44*(1-$K44) -> 500 | M44: =I44*(1-$K44) -> 0 | N44: =J44*(1-$K44) -> 15 | O44: =(L44+M44+N44) -> 515 | P44: =O44*$P$4 -> 0 | Q44: =(O44+P44)*$Q$4 -> 0 | R44: =(O44+P44)*$R$4 -> 10.3 | S44: =(O44+P44)*$S$4 -> 25.75 | T44: =SUM(O44:S44) -> 551.05 | U44: =5*$U$5+600+500 -> 1550 | V44: =V33 -> 0 | W44: =W33 -> 0 | X44: =SUM(U44:W44) -> 1550 | Y44: =$Y$4/(1-$Y$4)*(T44+X44+Z44+AA44) -> 463.46691 | Z44: =T44*$Z$4 -> 137.7625 | AA44: =X44*$AA$4 -> 387.5 | AB44: =T44+X44+Y44+Z44+AA44 -> 3089.7794 | AC44: =O44*$C44 -> 515 | AD44: =P44*$C44 -> 0 | AE44: =Q44*$C44 -> 0 | AF44: =R44*$C44 -> 10.3 | AG44: =S44*$C44 -> 25.75 | AH44: =T44*$C44 -> 551.05 | AI44: =U44*$C44 -> 1550 | AJ44: =V44*$C44 -> 0 | ... AO44: =AA44*$C44 -> 387.5 | AP44: =AM44+AK44 -> 463.46691 | AQ44: =AM44+AL44+AH44 -> 2564.5169 | AR44: =AO44+AN44 -> 525.2625 | AS44: =AH44+AL44+AM44+AO44+AN44 -> 3089.7794
B45: Echafaudage jusqu'à 6m de hauteur | C45: 1 | D45: Forfait | E45: =AB45 -> 2308.5 | F45: =C45*E45 -> 2308.5 | H45: =H12 -> 1300 | I45: =I12 -> 200 | J45: =H45*$J$4 -> 39 | K45: 0 | L45: =H45*(1-$K45) -> 1300 | M45: =I45*(1-$K45) -> 200 | N45: =J45*(1-$K45) -> 39 | O45: =(L45+M45+N45) -> 1539 | P45: =O45*$P$4 -> 0 | Q45: =(O45+P45)*$Q$4 -> 0 | R45: =(O45+P45)*$R$4 -> 30.78 | S45: 0 | T45: =SUM(O45:S45) -> 1569.78 | U45: 0 | V45: =V34 -> 0 | W45: =W34 -> 0 | X45: =SUM(U45:W45) -> 0 | Y45: =$Y$4/(1-$Y$4)*(T45+X45+Z45+AA45) -> 346.275 | Z45: =T45*$Z$4 -> 392.445 | AA45: =X45*$AA$4 -> 0 | AB45: =T45+X45+Y45+Z45+AA45 -> 2308.5 | AC45: =O45*$C45 -> 1539 | AD45: =P45*$C45 -> 0 | AE45: =Q45*$C45 -> 0 | AF45: =R45*$C45 -> 30.78 | AG45: =S45*$C45 -> 0 | AH45: =T45*$C45 -> 1569.78 | AI45: =U45*$C45 -> 0 | AJ45: =V45*$C45 -> 0 | ... AO45: =AA45*$C45 -> 0 | AP45: =AM45+AK45 -> 346.275 | AQ45: =AM45+AL45+AH45 -> 1916.055 | AR45: =AO45+AN45 -> 392.445 | AS45: =AH45+AL45+AM45+AO45+AN45 -> 2308.5
B46: Travaux administratifs | C46: 1 | D46: Forfait | E46: =AB46 -> 900 | F46: =C46*E46 -> 900 | H46: 0 | I46: 0 | J46: =H46*$J$4 -> 0 | K46: 0 | L46: =H46*(1-$K46) -> 0 | M46: =I46*(1-$K46) -> 0 | N46: =J46*(1-$K46) -> 0 | O46: =(L46+M46+N46) -> 0 | P46: =O46*$P$4 -> 0 | Q46: =(O46+P46)*$Q$4 -> 0 | R46: =(O46+P46)*$R$4 -> 0 | S46: 0 | T46: =SUM(O46:S46) -> 0 | U46: 0 | V46: =V35 -> 0 | W46: =W35 -> 900 | X46: =SUM(U46:W46) -> 900 | Y46: 0 | Z46: =T46*$Z$4 -> 0 | AA46: 0 | AB46: =T46+X46+Y46+Z46+AA46 -> 900 | AC46: =O46*$C46 -> 0 | AD46: =P46*$C46 -> 0 | AE46: =Q46*$C46 -> 0 | AF46: =R46*$C46 -> 0 | AG46: =S46*$C46 -> 0 | AH46: =T46*$C46 -> 0 | AI46: =U46*$C46 -> 0 | AJ46: =V46*$C46 -> 0 | ... AO46: =AA46*$C46 -> 0 | AP46: =AM46+AK46 -> 900 | AQ46: =AM46+AL46+AH46 -> 900 | AR46: =AO46+AN46 -> 0 | AS46: =AH46+AL46+AM46+AO46+AN46 -> 900
B47: Travaux électriques, contrôle et Pronovo | C47: 1 | D47: Forfait | E47: =AB47 -> 1200 | F47: =C47*E47 -> 1200 | H47: 0 | I47: 0 | J47: =H47*$J$4 -> 0 | K47: 0 | L47: =H47*(1-$K47) -> 0 | M47: =I47*(1-$K47) -> 0 | N47: =J47*(1-$K47) -> 0 | O47: =(L47+M47+N47) -> 0 | P47: =O47*$P$4 -> 0 | Q47: =(O47+P47)*$Q$4 -> 0 | R47: =(O47+P47)*$R$4 -> 0 | S47: 0 | T47: =SUM(O47:S47) -> 0 | U47: 0 | V47: =V36 -> 1200 | W47: =W36 -> 0 | X47: =SUM(U47:W47) -> 1200 | Y47: 0 | Z47: =T47*$Z$4 -> 0 | AA47: 0 | AB47: =T47+X47+Y47+Z47+AA47 -> 1200 | AC47: =O47*$C47 -> 0 | AD47: =P47*$C47 -> 0 | AE47: =Q47*$C47 -> 0 | AF47: =R47*$C47 -> 0 | AG47: =S47*$C47 -> 0 | AH47: =T47*$C47 -> 0 | AI47: =U47*$C47 -> 0 | AJ47: =V47*$C47 -> 1200 | ... AO47: =AA47*$C47 -> 0 | AP47: =AM47+AK47 -> 0 | AQ47: =AM47+AL47+AH47 -> 1200 | AR47: =AO47+AN47 -> 0 | AS47: =AH47+AL47+AM47+AO47+AN47 -> 1200
...

Sheet Fronius-Hybrid-10 to 30P
A1: N° | B1: DESCRIPTION | C1: QUANTITE | D1: UNITE DE MESURE | E1: PRIX UNITAIRE | F1: PRIX TOTAL | H1: Calcul Matériel | O1: Approvisionnement | U1: Construction | Y1: Sales | Z1: Profit | AB1: P.U. CHF | AC1: TOTAL Approvisionnement | AI1: TOTAL Construction | AM1: Sales | AN1: TOTAL Profit | AP1: TOTAL Frais | AQ1: COUT TOTAL | AR1: PROFIT TOTAL | AS1: PRIX TOTAL | AU1: Appro. Matériel Net | AW1: Main-d'œuvre Construction | AY1: Project Management | BA1: Frais Administratifs et Sales | BC1: Profit | BF1: Cout Total | BH1: Profit | BK1: Prix TTC | BM1: Pronovo | BN1: Prix Pronovo TTC | BO1: Prix TTC/kWc
E2: CHF (HT) | F2: CHF (HT) | H2: Matériel Avant Rabais | L2: Matériel Après Rabais | O2: Matériel Net | P2: Expédition | Q2: Douanes | R2: Frais Supp. | S2: Transport | T2: P.U. Matériel | U2: Main-d'œuvre | V2: Project Management | W2: Frais Administratifs | X2: P.U. Construction | Y2: Frais Généraux Sales | Z2: Profit Appro | AA2: Profit Construction | AC2: TOTAL Matériel Net | AD2: TOTAL Expédition | AE2: TOTAL Douanes | AF2: TOTAL Frais Supp. | AG2: TOTAL Transport | AH2: TOTAL Approvision-nement | AI2: TOTAL Main-d'œuvre | AJ2: TOTAL Project Management | AK2: TOTAL Frais Administratifs | AL2: TOTAL Construction | AM2: TOTAL Frais Généraux Sales | AN2: TOTAL Profit Appro. | AO2: TOTAL Profit Construction | AP2: TOTAL Frais Administratifs et Ingénierie
B3: Choisir le panneau : | H3: MAT (1) | I3: MAT (2) | J3: ACC | K3: Rabais | L3: MAT (1) | M3: MAT (2) | N3: ACC
B4: Longi 485W Full Black | J4: ='Financial Data'!$C$3 -> 0.03 | P4: ='Financial Data'!C4 -> 0 | Q4: ='Financial Data'!C5 -> 0 | R4: ='Financial Data'!C6 -> 0.02 | S4: ='Financial Data'!C7 -> 0.05 | U4: ='Financial Data'!C8 -> 65 | V4: ='Financial Data'!C10 -> 1200 | W4: ='Financial Data'!C11 -> 900 | Y4: ='Financial Data'!C12 -> 0.15 | Z4: ='Financial Data'!C13 -> 0.25 | AA4: ='Financial Data'!C14 -> 0.25
A5: 10 | B5: Panneaux | C5: Puissance: | D5: =ROUNDUP((A5*465)/1000,2) -> 4.65 | F5: =SUM(F6:F15) -> 16493.471 | U5: ='Financial Data'!C9 -> 90 | AC5: =+SUM(AC6:AC15) -> 6303.2805 | AD5: =+SUM(AD6:AD15) -> 0 | AE5: =+SUM(AE6:AE15) -> 0 | AF5: =+SUM(AF6:AF15) -> 126.06561 | AG5: =+SUM(AG6:AG15) -> 238.21402 | AH5: =+SUM(AH6:AH15) -> 6667.5601 | AI5: =+SUM(AI6:AI15) -> 3120 | AJ5: =+SUM(AJ6:AJ15) -> 1200 | ... AS5: =+SUM(AS6:AS15) -> 16493.471 | AT5: =IF(F5=AS5,"Matching","Not Matching") -> Matching | AU5: =SUM(AC5:AG5) -> 6667.5601 | AV5: =AU5/AS5 -> 0.40425452 | AW5: =AI5 -> 3120 | AX5: =AW5/AS5 -> 0.18916576 | AY5: =AJ5 -> 1200 | AZ5: =AY5/AS5 -> 0.072756063 | BA5: =AK5+AM5 -> 3059.0206 | BB5: =BA5/AS5 -> 0.18546858 | BC5: =AN5+AO5 -> 2446.89 | BD5: =BC5/AS5 -> 0.14835507 | BE5: =IF((AU5+AW5+AY5+BA5+BC5)=AS5,"Matching","Not Matching") -> Matching | BF5: =AQ5 -> 14046.581 | BG5: =BF5/AS5 -> 0.85164493 | BH5: =AR5 -> 2446.89 | BI5: =BH5/AS5 -> 0.14835507 | BJ5: =IF((BH5+BF5)=AS5,"Matching","Not Matching") -> Matching | BK5: =AS5*1.081 -> 17829.442 | BL5: =ROUND(BK5,-1) -> 17830 | BM5: =D5*380 -> 1767 | BN5: =BK5-BM5 -> 16062.442 | BO5: =BK5/D5 -> 3834.2886
I6: Parafoudres
B7: ="Panneau solaire "&G7 -> Panneau solaire LONGi Hi-MO X10 Artist LR7-54HVB-485M | C7: =A5 -> 10 | D7: U | E7: =AB7 -> 266.65685 | F7: =C7*E7 -> 2666.5685 | G7: =IF($B4="Jinko 455W Non Full Black",'Technical Data'!B3,IF($B4="Jinko 465W Full Black",'Technical Data'!B4,IF($B4="Longi 485W Non Full Black",'Technical Data'!B5,IF($B4="Longi 485W Full Black",'Technical Data'!B6,IF($B4="Aiko 480W Non Full Black",'Technical Data'!B7,IF($B4="Aiko 485W Full Black",'Technical Data'!B8,IF(ISBLANK($B4)," "))))))) -> LONGi Hi-MO X10 Artist LR7-54HVB-485M | H7: =IF($B4="Jinko 455W Non Full Black",'Financial Data'!$C$25,IF($B4="Jinko 465W Full Black",'Financial Data'!$C$26,IF($B4="Longi 485W Non Full Black",'Financial Data'!$C$27,IF($B4="Longi 485W Full Black",'Financial Data'!$C$28,IF($B4="Aiko 480W Non Full Black",'Financial Data'!$C$29,IF($B4="Aiko 485W Full Black",'Financial Data'!$C$30,IF(ISBLANK($B4),'Technical Data'!#REF!))))))) -> 105.55 | I7: ='Financial Data'!C56 -> 0 | J7: =H7*$J$4 -> 3.1665 | K7: 0 | L7: =H7*(1-$K7) -> 105.55 | M7: =I7*(1-$K7) -> 0 | N7: =J7*(1-$K7) -> 3.1665 | O7: =(L7+M7+N7) -> 108.7165 | P7: =O7*$P$4 -> 0 | Q7: =(O7+P7)*$Q$4 -> 0 | R7: =(O7+P7)*$R$4 -> 2.17433 | S7: =(O7+P7)*$S$4 -> 5.435825 | T7: =SUM(O7:S7) -> 116.32665 | U7: =1*$U$4 -> 65 | V7: 0 | W7: 0 | X7: =SUM(U7:W7) -> 65 | Y7: =$Y$4/(1-$Y$4)*(T7+X7+Z7+AA7) -> 39.998527 | Z7: =T7*$Z$4 -> 29.081664 | AA7: =X7*$AA$4 -> 16.25 | AB7: =T7+X7+Y7+Z7+AA7 -> 266.65685 | AC7: =O7*$C7 -> 1087.165 | AD7: =P7*$C7 -> 0 | AE7: =Q7*$C7 -> 0 | AF7: =R7*$C7 -> 21.7433 | AG7: =S7*$C7 -> 54.35825 | AH7: =T7*$C7 -> 1163.2665 | AI7: =U7*$C7 -> 650 | AJ7: =V7*$C7 -> 0 | ... AO7: =AA7*$C7 -> 162.5 | AP7: =AM7+AK7 -> 399.98527 | AQ7: =AM7+AL7+AH7 -> 2213.2518 | AR7: =AO7+AN7 -> 453.31664 | AS7: =AH7+AL7+AM7+AO7+AN7 -> 2666.5685
B8: ="Onduleur Fronius "&G8 -> Onduleur Fronius Symo GEN24 6.0 SC | C8: 1 | D8: U | E8: =AB8 -> 3133.4317 | F8: =C8*E8 -> 3133.4317 | G8: ='Financial Data'!B42 -> Symo GEN24 6.0 SC | H8: ='Financial Data'!C42 -> 1333.85 | I8: ='Financial Data'!C53+'Financial Data'!C54+'Financial Data'!C55 -> 449.25 | J8: =H8*$J$4 -> 40.0155 | K8: 0 | L8: =H8*(1-$K8) -> 1333.85 | M8: =I8*(1-$K8) -> 449.25 | N8: =J8*(1-$K8) -> 40.0155 | O8: =(L8+M8+N8) -> 1823.1155 | P8: =O8*$P$4 -> 0 | Q8: =(O8+P8)*$Q$4 -> 0 | R8: =(O8+P8)*$R$4 -> 36.46231 | S8: =(O8+P8)*$S$4 -> 91.155775 | T8: =SUM(O8:S8) -> 1950.7336 | U8: =2*$U$5 -> 180 | V8: 0 | W8: 0 | X8: =SUM(U8:W8) -> 180 | Y8: =$Y$4/(1-$Y$4)*(T8+X8+Z8+AA8) -> 470.01476 | Z8: =T8*$Z$4 -> 487.6834 | AA8: =X8*$AA$4 -> 45 | AB8: =T8+X8+Y8+Z8+AA8 -> 3133.4317 | AC8: =O8*$C8 -> 1823.1155 | AD8: =P8*$C8 -> 0 | AE8: =Q8*$C8 -> 0 | AF8: =R8*$C8 -> 36.46231 | AG8: =S8*$C8 -> 91.155775 | AH8: =T8*$C8 -> 1950.7336 | AI8: =U8*$C8 -> 180 | AJ8: =V8*$C8 -> 0 | ... AO8: =AA8*$C8 -> 45 | AP8: =AM8+AK8 -> 470.01476 | AQ8: =AM8+AL8+AH8 -> 2600.7483 | AR8: =AO8+AN8 -> 532.6834 | AS8: =AH8+AL8+AM8+AO8+AN8 -> 3133.4317
B9: Accessoires | C9: 1 | D9: Forfait | E9: =AB9 -> 618.57353 | F9: =C9*E9 -> 618.57353 | H9: 300 | I9: 0 | J9: =H9*$J$4 -> 9 | K9: 0 | L9: =H9*(1-$K9) -> 300 | M9: =I9*(1-$K9) -> 0 | N9: =J9*(1-$K9) -> 9 | O9: =(L9+M9+N9) -> 309 | P9: =O9*$P$4 -> 0 | Q9: =(O9+P9)*$Q$4 -> 0 | R9: =(O9+P9)*$R$4 -> 6.18 | S9: =(O9+P9)*$S$4 -> 15.45 | T9: =SUM(O9:S9) -> 330.63 | U9: =(C7/10)*$U$5 -> 90 | V9: 0 | W9: 0 | X9: =SUM(U9:W9) -> 90 | Y9: =$Y$4/(1-$Y$4)*(T9+X9+Z9+AA9) -> 92.786029 | Z9: =T9*$Z$4 -> 82.6575 | AA9: =X9*$AA$4 -> 22.5 | AB9: =T9+X9+Y9+Z9+AA9 -> 618.57353 | AC9: =O9*$C9 -> 309 | AD9: =P9*$C9 -> 0 | AE9: =Q9*$C9 -> 0 | AF9: =R9*$C9 -> 6.18 | AG9: =S9*$C9 -> 15.45 | AH9: =T9*$C9 -> 330.63 | AI9: =U9*$C9 -> 90 | AJ9: =V9*$C9 -> 0 | ... AO9: =AA9*$C9 -> 22.5 | AP9: =AM9+AK9 -> 92.786029 | AQ9: =AM9+AL9+AH9 -> 513.41603 | AR9: =AO9+AN9 -> 105.1575 | AS9: =AH9+AL9+AM9+AO9+AN9 -> 618.57353
B10: Système de montage sur tuile | C10: =A5 -> 10 | D10: U | E10: =AB10 -> 257.66176 | F10: =C10*E10 -> 2576.6176 | H10: 100 | I10: 0 | J10: =H10*$J$4 -> 3 | K10: 0 | L10: =H10*(1-$K10) -> 100 | M10: =I10*(1-$K10) -> 0 | N10: =J10*(1-$K10) -> 3 | O10: =(L10+M10+N10) -> 103 | P10: =O10*$P$4 -> 0 | Q10: =(O10+P10)*$Q$4 -> 0 | R10: =(O10+P10)*$R$4 -> 2.06 | S10: =(O10+P10)*$S$4 -> 5.15 | T10: =SUM(O10:S10) -> 110.21 | U10: =1*$U$4 -> 65 | V10: 0 | W10: 0 | X10: =SUM(U10:W10) -> 65 | Y10: =$Y$4/(1-$Y$4)*(T10+X10+Z10+AA10) -> 38.649265 | Z10: =T10*$Z$4 -> 27.5525 | AA10: =X10*$AA$4 -> 16.25 | AB10: =T10+X10+Y10+Z10+AA10 -> 257.66176 | AC10: =O10*$C10 -> 1030 | AD10: =P10*$C10 -> 0 | AE10: =Q10*$C10 -> 0 | AF10: =R10*$C10 -> 20.6 | AG10: =S10*$C10 -> 51.5 | AH10: =T10*$C10 -> 1102.1 | AI10: =U10*$C10 -> 650 | AJ10: =V10*$C10 -> 0 | ... AO10: =AA10*$C10 -> 162.5 | AP10: =AM10+AK10 -> 386.49265 | AQ10: =AM10+AL10+AH10 -> 2138.5926 | AR10: =AO10+AN10 -> 438.025 | AS10: =AH10+AL10+AM10+AO10+AN10 -> 2576.6176
B11: Raccordement AC | C11: 1 | D11: Forfait | E11: =AB11 -> 3089.7794 | F11: =C11*E11 -> 3089.7794 | H11: 500 | I11: 0 | J11: =H11*$J$4 -> 15 | K11: 0 | L11: =H11*(1-$K11) -> 500 | M11: =I11*(1-$K11) -> 0 | N11: =J11*(1-$K11) -> 15 | O11: =(L11+M11+N11) -> 515 | P11: =O11*$P$4 -> 0 | Q11: =(O11+P11)*$Q$4 -> 0 | R11: =(O11+P11)*$R$4 -> 10.3 | S11: =(O11+P11)*$S$4 -> 25.75 | T11: =SUM(O11:S11) -> 551.05 | U11: =5*$U$5+600+500 -> 1550 | V11: 0 | W11: 0 | X11: =SUM(U11:W11) -> 1550 | Y11: =$Y$4/(1-$Y$4)*(T11+X11+Z11+AA11) -> 463.46691 | Z11: =T11*$Z$4 -> 137.7625 | AA11: =X11*$AA$4 -> 387.5 | AB11: =T11+X11+Y11+Z11+AA11 -> 3089.7794 | AC11: =O11*$C11 -> 515 | AD11: =P11*$C11 -> 0 | AE11: =Q11*$C11 -> 0 | AF11: =R11*$C11 -> 10.3 | AG11: =S11*$C11 -> 25.75 | AH11: =T11*$C11 -> 551.05 | AI11: =U11*$C11 -> 1550 | AJ11: =V11*$C11 -> 0 | ... AO11: =AA11*$C11 -> 387.5 | AP11: =AM11+AK11 -> 463.46691 | AQ11: =AM11+AL11+AH11 -> 2564.5169 | AR11: =AO11+AN11 -> 525.2625 | AS11: =AH11+AL11+AM11+AO11+AN11 -> 3089.7794
B12: Echafaudage jusqu'à 6m de hauteur | C12: 1 | D12: Forfait | E12: =AB12 -> 2308.5 | F12: =C12*E12 -> 2308.5 | H12: 1300 | I12: 200 | J12: =H12*$J$4 -> 39 | K12: 0 | L12: =H12*(1-$K12) -> 1300 | M12: =I12*(1-$K12) -> 200 | N12: =J12*(1-$K12) -> 39 | O12: =(L12+M12+N12) -> 1539 | P12: =O12*$P$4 -> 0 | Q12: =(O12+P12)*$Q$4 -> 0 | R12: =(O12+P12)*$R$4 -> 30.78 | S12: 0 | T12: =SUM(O12:S12) -> 1569.78 | U12: 0 | V12: 0 | W12: 0 | X12: =SUM(U12:W12) -> 0 | Y12: =$Y$4/(1-$Y$4)*(T12+X12+Z12+AA12) -> 346.275 | Z12: =T12*$Z$4 -> 392.445 | AA12: =X12*$AA$4 -> 0 | AB12: =T12+X12+Y12+Z12+AA12 -> 2308.5 | AC12: =O12*$C12 -> 1539 | AD12: =P12*$C12 -> 0 | AE12: =Q12*$C12 -> 0 | AF12: =R12*$C12 -> 30.78 | AG12: =S12*$C12 -> 0 | AH12: =T12*$C12 -> 1569.78 | AI12: =U12*$C12 -> 0 | AJ12: =V12*$C12 -> 0 | ... AO12: =AA12*$C12 -> 0 | AP12: =AM12+AK12 -> 346.275 | AQ12: =AM12+AL12+AH12 -> 1916.055 | AR12: =AO12+AN12 -> 392.445 | AS12: =AH12+AL12+AM12+AO12+AN12 -> 2308.5
B13: Travaux administratifs | C13: 1 | D13: Forfait | E13: =AB13 -> 900 | F13: =C13*E13 -> 900 | H13: 0 | I13: 0 | J13: =H13*$J$4 -> 0 | K13: 0 | L13: =H13*(1-$K13) -> 0 | M13: =I13*(1-$K13) -> 0 | N13: =J13*(1-$K13) -> 0 | O13: =(L13+M13+N13) -> 0 | P13: =O13*$P$4 -> 0 | Q13: =(O13+P13)*$Q$4 -> 0 | R13: =(O13+P13)*$R$4 -> 0 | S13: 0 | T13: =SUM(O13:S13) -> 0 | U13: 0 | V13: 0 | W13: =$W$4 -> 900 | X13: =SUM(U13:W13) -> 900 | Y13: 0 | Z13: =T13*$Z$4 -> 0 | AA13: 0 | AB13: =T13+X13+Y13+Z13+AA13 -> 900 | AC13: =O13*$C13 -> 0 | AD13: =P13*$C13 -> 0 | AE13: =Q13*$C13 -> 0 | AF13: =R13*$C13 -> 0 | AG13: =S13*$C13 -> 0 | AH13: =T13*$C13 -> 0 | AI13: =U13*$C13 -> 0 | AJ13: =V13*$C13 -> 0 | ... AO13: =AA13*$C13 -> 0 | AP13: =AM13+AK13 -> 900 | AQ13: =AM13+AL13+AH13 -> 900 | AR13: =AO13+AN13 -> 0 | AS13: =AH13+AL13+AM13+AO13+AN13 -> 900
B14: Travaux électriques, contrôle et Pronovo | C14: 1 | D14: Forfait | E14: =AB14 -> 1200 | F14: =C14*E14 -> 1200 | H14: 0 | I14: 0 | J14: =H14*$J$4 -> 0 | K14: 0 | L14: =H14*(1-$K14) -> 0 | M14: =I14*(1-$K14) -> 0 | N14: =J14*(1-$K14) -> 0 | O14: =(L14+M14+N14) -> 0 | P14: =O14*$P$4 -> 0 | Q14: =(O14+P14)*$Q$4 -> 0 | R14: =(O14+P14)*$R$4 -> 0 | S14: 0 | T14: =SUM(O14:S14) -> 0 | U14: 0 | V14: =$V$4 -> 1200 | W14: 0 | X14: =SUM(U14:W14) -> 1200 | Y14: 0 | Z14: =T14*$Z$4 -> 0 | AA14: 0 | AB14: =T14+X14+Y14+Z14+AA14 -> 1200 | AC14: =O14*$C14 -> 0 | AD14: =P14*$C14 -> 0 | AE14: =Q14*$C14 -> 0 | AF14: =R14*$C14 -> 0 | AG14: =S14*$C14 -> 0 | AH14: =T14*$C14 -> 0 | AI14: =U14*$C14 -> 0 | AJ14: =V14*$C14 -> 1200 | ... AO14: =AA14*$C14 -> 0 | AP14: =AM14+AK14 -> 0 | AQ14: =AM14+AL14+AH14 -> 1200 | AR14: =AO14+AN14 -> 0 | AS14: =AH14+AL14+AM14+AO14+AN14 -> 1200
